Workbook

Sheet DANH SÁCH 1
A1: STT | B1: Họ và tên | C1: Ngày sinh | D1: Số CMND/HC | E1: Địa chỉ thường trú | F1: GV
A2: 1 | B2: TRẦN NGUYỄN TRÂM ANH | C2: 27/11/1988 | D2: 052188000709 | E2: 68/45 Trần Quang Khải P. Tân Định, Q.1, TP. Hồ Chí Minh | F2: C BẢO
A3: 2 | B3: HỒ TRẦN NHẤT DUY | C3: 16/04/2003 | D3: 074203009035 | E3: 266/15/1/6 Tổ 23 Khu 2 P. Hiệp Thành, TP. Thủ Dầu Một, T. Bình Dương | F3: C BẢO
A4: 3 | B4: NGUYỄN THỊ BÍCH NGỌC | C4: 15/07/1990 | D4: 075190025873 | E4: 2 Trung Lang P.12, Q. Tân Bình, TP. Hồ Chí Minh | F4: CHUNG VÂN
A5: 4 | B5: LÊ QUANG HIỀN | C5: 04/10/1986 | D5: 079086002654 | E5: Tổ 71 Ấp Cây Trâm X. Phú Hòa Đông, H. Củ Chi, TP. Hồ Chí Minh | F5: DANH
A6: 5 | B6: PHẠM VĂN HOAN | C6: 20/05/1981 | D6: 074081005167 | E6: Ấp Rạch Đá X. Định Thành, H. Dầu Tiếng, T. Bình Dương | F6: DỰ
A7: 6 | B7: NGUYỄN PHAN THU HUYỀN | C7: 02/07/1995 | D7: 074195002718 | E7: Khu Phố 4B TT. Dầu Tiếng, H. Dầu Tiếng, T. Bình Dương | F7: DỰ
A8: 7 | B8: SU LIUQIAO | C8: 08/02/1988 | D8: EH6354689 | E8: B83-84 Kdc Việt Sing P. An Phú, TP. Thuận An, T. Bình Dương | F8: DỰ
A9: 8 | B9: LA THANH THÙY | C9: 20/04/1995 | D9: 074195000421 | E9: Khu Phố 4B TT. Dầu Tiếng, H. Dầu Tiếng, T. Bình Dương | F9: DỰ
A10: 9 | B10: DƯƠNG MỸ TRANG | C10: 10/08/1986 | D10: 074186004976 | E10: Ấp Bàu Dầu X. Định An, H. Dầu Tiếng, T. Bình Dương | F10: DỰ
A11: 10 | B11: HUỲNH THỊ Ý | C11: 12/03/1991 | D11: 074191000640 | E11: Khu Phố 2 TT. Dầu Tiếng, H. Dầu Tiếng, T. Bình Dương | F11: DỰ
A12: 11 | B12: ĐẶNG VĂN QUANG | C12: 17/07/1997 | D12: 079097011123 | E12: 257/34 P. Đ. Giảng P. Bình Hưng Hòa, Q. Bình Tân, TP. Hồ Chí Minh | F12: DŨNG HM
A13: 12 | B13: DƯƠNG YẾN NHI | C13: 14/10/2005 | D13: 079305019526 | E13: F12/16 Tổ 1 Ấp 6A X. Vĩnh Lộc A, H. Bình Chánh, TP. Hồ Chí Minh | F13: HOÀNG CC
... A46: 45 | B46: TRẦN THỊ NGỌC YẾN | C46: 03/09/1994 | D46: 087194007059 | E46: B04-03 C/C Theharmona P.14, Q. Tân Bình, TP. Hồ Chí Minh | F46: VIỆT NHỎ

Sheet DANH SÁCH
A1: HẠNG | C1: B11 | D1: KHÓA | E1: 79029K23B11029 | G1: TÊN KHÓA | I1: K29
A2: Nhóm | B2: STT | C2: Họ và tên | D2: Ngày sinh | E2: Số CMND | F2: Nơi cư trú | G2: Gv | H2: GV DAT | I2: SỐ XE | J2: Ghi chú | K2: STT | L2: GVKH | M2: Xe KH | N2: Chủ xe | O2: Hạn giấy phép xe tập lái
A3: 1 | B3: 1 | C3: TRẦN NGUYỄN TRÂM ANH | D3: 27/11/1988 | E3: 052188000709 | F3: 68/45 Trần Quang Khải P. Tân Định, Q.1, TP. Hồ Chí Minh | G3: C BẢO | H3: LÊ VĂN TẪN | I3: 51G-10327 | K3: 1 | L3: NGUYỄN CÔNG BẰNG | M3: 47A-72717 | N3: T HƯNG A1 | O3: 45748
B4: 2 | C4: HỒ TRẦN NHẤT DUY | D4: 16/04/2003 | E4: 074203009035 | F4: 266/15/1/6 Tổ 23 Khu 2 P. Hiệp Thành, TP. Thủ Dầu Một, T. Bình Dương | G4: C BẢO | K4: 2 | L4: NGUYỄN THỊ KIM DUNG | M4: 51K-21807 | N4: T MINH | O4: 45926
B5: 3 | C5: PHẠM THỊ DUY TRINH | D5: 19/11/2001 | E5: 064301008069 | F5: Thôn 4 X. Đắk Búk So, H. Tuy Đức, T. Đắk Nông | G5: VIỆT NHỎ | K5: 3 | L5: TRẦN TRÍ HƯỚNG | M5: 51K-85525 | N5: LÊ TẤN LỢI | O5: 46109
B6: 4 | C6: VÕ DUY VIỆN | D6: 01/07/2002 | E6: 067202002769 | F6: Thôn 8 X. Nhân Cơ, H. Đắk R'Lấp, T. Đắk Nông | G6: VIỆT NHỎ | K6: 4 | L6: NGUYỄN VĂN MINH | M6: 62A-10055 | N6: T NGUYÊN-BẢO | O6: 46147
B7: 5 | C7: TRẦN THỊ NGỌC YẾN | D7: 03/09/1994 | E7: 087194007059 | F7: B04-03 C/C Theharmona P.14, Q. Tân Bình, TP. Hồ Chí Minh | G7: VIỆT NHỎ | K7: 5 | L7: LÊ THÀNH NAM | M7: 61A-78409 | N7: C HƯƠNG-TIẾN | O7: 46114
A8: 2 | B8: 1 | C8: ĐẶNG VĂN QUANG | D8: 17/07/1997 | E8: 079097011123 | F8: 257/34 P. Đ. Giảng P. Bình Hưng Hòa, Q. Bình Tân, TP. Hồ Chí Minh | G8: DŨNG HM | H8: PHẠM MINH TUẤN | I8: 51G-80494 | K8: 6 | L8: LÊ THỊ NGẦN | M8: 51A-92569 | N8: T HƯNG A1 | O8: 45723
B9: 2 | C9: HÀ BẢO QUỲNH ANH | D9: 10/02/1996 | E9: 070196006321 | F9: Khu Phố Phú Tân P. Tân Phú, TX. Đồng Xoài, T. Bình Phước | G9: LIÊN CÔNG | K9: 7 | L9: NGUYỄN HẢI SƠN | M9: 61A-776.34 | O9: 25/07/26
B10: 3 | C10: NGUYỄN THỊ PHƯƠNG DUNG | D10: 03/10/1994 | E10: 095194005147 | F10: TT. Giá Rai, H. Giá Rai, T. Bạc Liêu | G10: LIÊN CÔNG | K10: 8 | L10: LÊ VĂN TẪN | M10: 51G-10327 | N10: C LÁNH | O10: 46095
B11: 4 | C11: A MI NA- BINROJAK | D11: 28/12/2004 | E11: 079304025386 | F11: 231D/5 Dương Bá Trạc P.01, Q.8, TP. Hồ Chí Minh | G11: LIÊN CÔNG | K11: 9 | L11: PHẠM MINH TUẤN | M11: 51G-80494 | N11: T CÔNG | O11: 46120
B12: 5 | C12: NGUYỄN VĂN TÚ | D12: 23/12/1984 | E12: 082084009569 | F12: 144/1A Lê Tấn Bê P. An Lạc, Q. Bình Tân, TP. Hồ Chí Minh | G12: LIÊN CÔNG | K12: 10
A13: 3 | B13: 1 | C13: NGUYỄN THỊ THU HỒNG | D13: 10/06/2003 | E13: 074303008825 | F13: 20/5A Kp Tây P. Vĩnh Phú, TP. Thuận An, T. Bình Dương | G13: LUẬT | H13: NGUYỄN THỊ KIM DUNG | I13: 51K-21807 | K13: 11
B14: 2 | C14: PHAN THỊ KIM HUỆ | D14: 10/01/1982 | E14: 001182055881 | F14: Thôn 3 X. Liên Đầm, H. Di Linh, T. Lâm Đồng | G14: LUẬT | K14: 12
B15: 3 | C15: LÊ THỊ YẾN NHI | D15: 30/06/1993 | E15: 042193010288 | F15: 5.04 Tháp C1 KNƠCT CT Saphire P. Phú Hữu, TP. Thủ Đức, TP. Hồ Chí Minh | G15: LUẬT | K15: 13
B16: 4 | C16: PHAN THỊ DIỆU THÚY | D16: 19/12/1993 | E16: 042193000509 | F16: T3-B25.05 Knở Ctkhtmdv P. Thảo Điền, TP. Thủ Đức, TP. Hồ Chí Minh | G16: LUẬT | K16: 14
B17: 5 | C17: BÙI VĂN HÙNG | D17: 11/04/1998 | E17: 068098009995 | F17: Thôn Đạ Sơn X. Đạ K' Nàng, H. Đam Rông, T. Lâm Đồng | G17: VÂN NỮ | K17: 15
A18: 4 | B18: 1 | C18: NGUYỄN THỊ BÍCH NGỌC | D18: 15/07/1990 | E18: 075190025873 | F18: 2 Trung Lang P.12, Q. Tân Bình, TP. Hồ Chí Minh | G18: CHUNG VÂN | H18: NGUYỄN VĂN MINH | I18: 62A-10055 | K18: 16
B19: 2 | C19: DƯƠNG YẾN NHI | D19: 14/10/2005 | E19: 079305019526 | F19: F12/16 Tổ 1 Ấp 6A X. Vĩnh Lộc A, H. Bình Chánh, TP. Hồ Chí Minh | G19: HOÀNG CC | K19: 17
B20: 3 | C20: NGUYỄN THỊ DÒN | D20: 27/09/1973 | E20: 082173017864 | F20: Ấp 1 X. Tam Hiệp, H. Châu Thành, T. Tiền Giang | G20: NAM RÂU | K20: 18
B21: 4 | C21: NGUYỄN THIỀU KIỀU DUNG | D21: 25/04/1998 | E21: 079198004113 | F21: A3/42B/3 Tổ 2 Ấp 1A X. Vĩnh Lộc A, H. Bình Chánh, TP. Hồ Chí Minh | G21: NAM RÂU | K21: 19
B22: 5 | C22: NGUYỄN THỊ CÁC TƯỜNG | D22: 26/03/2001 | E22: 087301005552 | F22: Ấp 1 X. Tân Nghĩa, H. Cao Lãnh, T. Đồng Tháp | G22: VÂN ĐX
A23: 5 | B23: 1 | C23: PHẠM VŨ THÚY VY | D23: 17/02/1993 | E23: 094193008223 | F23: 319 Quốc Lộ 1 P. 6, TP. Sóc Trăng, T. Sóc Trăng | G23: TUẤN ANH | H23: NGUYỄN HẢI SƠN | I23: 61A-776.34
B24: 2 | C24: NGUYỄN THỊ HỒNG NGỌC | D24: 13/05/2001 | E24: 082301007233 | F24: Ấp Ông Non X. Tân Trung, TX. Gò Công, T. Tiền Giang | G24: MINH (THỨC)
B25: 3 | C25: NGÔ VĂN CẦN | D25: 11/09/1997 | E25: 036097003979 | F25: Xóm 13 X. Yên Nhân, H. ý Yên, T. Nam Định | G25: LINH KT
B26: 4 | C26: VŨ VĂN HOÀNH | D26: 11/12/1968 | E26: 024068000170 | F26: 244/20/12 Kp4 P. Thới An, Q.12, TP. Hồ Chí Minh | G26: LINH KT
B27: 5 | C27: NGÔ MINH VƯƠNG | D27: 16/01/1992 | E27: 051092012665 | F27: 41/23/9 Tổ 10 Kp4 P. Tân Thới Hiệp, Q.12, TP. Hồ Chí Minh | G27: LINH KT
A28: 6 | B28: 1 | C28: NGUYỄN THỊ NGỌC HÂN | D28: 15/06/2004 | E28: 086304000053 | F28: 56/2 Đ. Số 8B P. Bình Hưng Hòa A, Q. Bình Tân, TP. Hồ Chí Minh | G28: THỨC | H28: TRẦN TRÍ HƯỚNG | I28: 51K-85525
B29: 2 | C29: TRƯƠNG THÚY LAN | D29: 04/06/1980 | E29: 079180001284 | F29: 479/11 Điện Biên Phủ P.25, Q. Bình Thạnh, TP. Hồ Chí Minh | G29: THỨC
B30: 3 | C30: NGUYỄN LƯU KIỀU NHI | D30: 06/10/1995 | E30: 068195005616 | F30: 150 Hồ Tùng Mậu P.1, TP. Bảo Lộc, T. Lâm Đồng | G30: THỨC
B31: 4 | C31: HÀ KIỀU TRINH | D31: 27/11/2006 | E31: 060306003174 | F31: 609/16/1 Nguyễn Ảnh Thủ Kp4 P. Hiệp Thành, Q.12, TP. Hồ Chí Minh | G31: THỨC
B32: 5 | C32: TRƯƠNG THỊ CÁT TƯỜNG | D32: 25/10/1999 | E32: 064199011211 | F32: Thôn 2 X. Ia HLốp, H. Chư Sê, T. Gia Lai | G32: THỨC
A33: 7 | B33: 1 | C33: LÊ QUANG HIỀN | D33: 04/10/1986 | E33: 079086002654 | F33: Tổ 71 Ấp Cây Trâm X. Phú Hòa Đông, H. Củ Chi, TP. Hồ Chí Minh | G33: DANH | H33: NGUYỄN CÔNG BẰNG | I33: 47A-72717
B34: 2 | C34: PHẠM THỊ HOA | D34: 16/09/1990 | E34: 038190056205 | F34: 34/46 ĐLBD Kp3 P. Phú Hòa, TP. Thủ Dầu Một, T. Bình Dương | G34: HƯNG A1
B35: 3 | C35: TRẦN THÀNH NHÂN | D35: 09/01/1987 | E35: 070087000026 | F35: Tổ 12 Ấp Chợ X. Phước Thạnh, H. Củ Chi, TP. Hồ Chí Minh | G35: PHƯƠNG G(S)
B36: 4 | C36: IN SÙI KHÍU | D36: 06/12/1990 | E36: 075190023067 | F36: Ấp 5 X. Phú Lợi, H. Định Quán, T. Đồng Nai | G36: TUYẾT
B37: 5 | C37: PHẠM VĂN HOAN | D37: 20/05/1981 | E37: 074081005167 | F37: Ấp Rạch Đá X. Định Thành, H. Dầu Tiếng, T. Bình Dương | G37: DỰ
A38: 8 | B38: 1 | C38: NGUYỄN PHAN THU HUYỀN | D38: 02/07/1995 | E38: 074195002718 | F38: Khu Phố 4B TT. Dầu Tiếng, H. Dầu Tiếng, T. Bình Dương | G38: DỰ | H38: LÊ THỊ NGẦN | I38: 51A-92569
B39: 2 | C39: SU LIUQIAO | D39: 08/02/1988 | E39: EH6354689 | F39: B83-84 Kdc Việt Sing P. An Phú, TP. Thuận An, T. Bình Dương | G39: DỰ
B40: 3 | C40: LA THANH THÙY | D40: 20/04/1995 | E40: 074195000421 | F40: Khu Phố 4B TT. Dầu Tiếng, H. Dầu Tiếng, T. Bình Dương | G40: DỰ
...

Sheet BÌA
C2: SỞ LAO ĐỘNG THƯƠNG BINH XÃ HỘI TP.HCM
C3: TRUNG TÂM GIÁO DỤC NGHỀ NGHIỆP TIẾN THÀNH
E5: SỔ THEO DÕI THỰC HÀNH LÁI XE
C10: Họ và tên giáo viên: | F10: …..................................................................
C11: Biển số xe tập lái số: | F11: …..................................................................
C13: Mã khóa: | E13: …......................................... | H13: Tên khóa: | J13: ….......... | K13: Hạng: | L13: ….......
C18: Năm 202…

Sheet SỔ THEO DÕI
B1: Hạng xe: | C1: ….............. | D1: Từ ngày: | E1: ….................. | F1: đến ngày: | G1: …............
B2: Mã Khóa: | C2: …................................................ | E2: Xe: | F2: …..........................
A4: DANH SÁCH HỌC VIÊN
A6: STT | B6: Họ và tên | C6: Ngày sinh | D6: Nơi cư trú | E6: Số km thực hành | F6: Điểm thi kiểm tra cuối khóa | G6: Học viên ký tên
A7: 1 | B7: ='DANH SÁCH'!C3 -> TRẦN NGUYỄN TRÂM ANH | C7: ='DANH SÁCH'!D3 -> 27/11/1988 | D7: ='DANH SÁCH'!F3 -> 68/45 Trần Quang Khải P. Tân Định, Q.1, TP. Hồ Chí Minh
A8: 2 | B8: ='DANH SÁCH'!C4 -> HỒ TRẦN NHẤT DUY | C8: ='DANH SÁCH'!D4 -> 16/04/2003 | D8: ='DANH SÁCH'!F4 -> 266/15/1/6 Tổ 23 Khu 2 P. Hiệp Thành, TP. Thủ Dầu Một, T. Bình Dương
A9: 3 | B9: ='DANH SÁCH'!C5 -> PHẠM THỊ DUY TRINH | C9: ='DANH SÁCH'!D5 -> 19/11/2001 | D9: ='DANH SÁCH'!F5 -> Thôn 4 X. Đắk Búk So, H. Tuy Đức, T. Đắk Nông
A10: 4 | B10: ='DANH SÁCH'!C6 -> VÕ DUY VIỆN | C10: ='DANH SÁCH'!D6 -> 01/07/2002 | D10: ='DANH SÁCH'!F6 -> Thôn 8 X. Nhân Cơ, H. Đắk R'Lấp, T. Đắk Nông
A11: 5 | B11: ='DANH SÁCH'!C7 -> TRẦN THỊ NGỌC YẾN | C11: ='DANH SÁCH'!D7 -> 03/09/1994 | D11: ='DANH SÁCH'!F7 -> B04-03 C/C Theharmona P.14, Q. Tân Bình, TP. Hồ Chí Minh
B13: Hạng xe: | C13: ….............. | D13: Từ ngày: | E13: ….................. | F13: đến ngày: | G13: …............
B14: Mã Khóa: | C14: …................................................ | E14: Xe: | F14: …..........................
A16: DANH SÁCH HỌC VIÊN
A18: STT | B18: Họ và tên | C18: Ngày sinh | D18: Nơi cư trú | E18: Số km thực hành | F18: Điểm thi kiểm tra cuối khóa | G18: Học viên ký tên
A19: 1 | B19: ='DANH SÁCH'!C8 -> ĐẶNG VĂN QUANG | C19: ='DANH SÁCH'!D8 -> 17/07/1997 | D19: ='DANH SÁCH'!F8 -> 257/34 P. Đ. Giảng P. Bình Hưng Hòa, Q. Bình Tân, TP. Hồ Chí Minh
A20: 2 | B20: ='DANH SÁCH'!C9 -> HÀ BẢO QUỲNH ANH | C20: ='DANH SÁCH'!D9 -> 10/02/1996 | D20: ='DANH SÁCH'!F9 -> Khu Phố Phú Tân P. Tân Phú, TX. Đồng Xoài, T. Bình Phước
A21: 3 | B21: ='DANH SÁCH'!C10 -> NGUYỄN THỊ PHƯƠNG DUNG | C21: ='DANH SÁCH'!D10 -> 03/10/1994 | D21: ='DANH SÁCH'!F10 -> TT. Giá Rai, H. Giá Rai, T. Bạc Liêu
A22: 4 | B22: ='DANH SÁCH'!C11 -> A MI NA- BINROJAK | C22: ='DANH SÁCH'!D11 -> 28/12/2004 | D22: ='DANH SÁCH'!F11 -> 231D/5 Dương Bá Trạc P.01, Q.8, TP. Hồ Chí Minh
A23: 5 | B23: ='DANH SÁCH'!C12 -> NGUYỄN VĂN TÚ | C23: ='DANH SÁCH'!D12 -> 23/12/1984 | D23: ='DANH SÁCH'!F12 -> 144/1A Lê Tấn Bê P. An Lạc, Q. Bình Tân, TP. Hồ Chí Minh
B25: Hạng xe: | C25: ….............. | D25: Từ ngày: | E25: ….................. | F25: đến ngày: | G25: …............
B26: Mã Khóa: | C26: …................................................ | E26: Xe: | F26: …..........................
A28: DANH SÁCH HỌC VIÊN
A30: STT | B30: Họ và tên | C30: Ngày sinh | D30: Nơi cư trú | E30: Số km thực hành | F30: Điểm thi kiểm tra cuối khóa | G30: Học viên ký tên
A31: 1 | B31: ='DANH SÁCH'!C13 -> NGUYỄN THỊ THU HỒNG | C31: ='DANH SÁCH'!D13 -> 10/06/2003 | D31: ='DANH SÁCH'!F13 -> 20/5A Kp Tây P. Vĩnh Phú, TP. Thuận An, T. Bình Dương
A32: 2 | B32: ='DANH SÁCH'!C14 -> PHAN THỊ KIM HUỆ | C32: ='DANH SÁCH'!D14 -> 10/01/1982 | D32: ='DANH SÁCH'!F14 -> Thôn 3 X. Liên Đầm, H. Di Linh, T. Lâm Đồng
A33: 3 | B33: ='DANH SÁCH'!C15 -> LÊ THỊ YẾN NHI | C33: ='DANH SÁCH'!D15 -> 30/06/1993 | D33: ='DANH SÁCH'!F15 -> 5.04 Tháp C1 KNƠCT CT Saphire P. Phú Hữu, TP. Thủ Đức, TP. Hồ Chí Minh
A34: 4 | B34: ='DANH SÁCH'!C16 -> PHAN THỊ DIỆU THÚY | C34: ='DANH SÁCH'!D16 -> 19/12/1993 | D34: ='DANH SÁCH'!F16 -> T3-B25.05 Knở Ctkhtmdv P. Thảo Điền, TP. Thủ Đức, TP. Hồ Chí Minh
A35: 5 | B35: ='DANH SÁCH'!C17 -> BÙI VĂN HÙNG | C35: ='DANH SÁCH'!D17 -> 11/04/1998 | D35: ='DANH SÁCH'!F17 -> Thôn Đạ Sơn X. Đạ K' Nàng, H. Đam Rông, T. Lâm Đồng
B37: Hạng xe: | C37: ….............. | D37: Từ ngày: | E37: ….................. | F37: đến ngày: | G37: …............
B38: Mã Khóa: | C38: …................................................ | E38: Xe: | F38: …..........................
A40: DANH SÁCH HỌC VIÊN
A42: STT | B42: Họ và tên | C42: Ngày sinh | D42: Nơi cư trú | E42: Số km thực hành | F42: Điểm thi kiểm tra cuối khóa | G42: Học viên ký tên
A43: 1 | B43: ='DANH SÁCH'!C18 -> NGUYỄN THỊ BÍCH NGỌC | C43: ='DANH SÁCH'!D18 -> 15/07/1990 | D43: ='DANH SÁCH'!F18 -> 2 Trung Lang P.12, Q. Tân Bình, TP. Hồ Chí Minh
A44: 2 | B44: ='DANH SÁCH'!C19 -> DƯƠNG YẾN NHI | C44: ='DANH SÁCH'!D19 -> 14/10/2005 | D44: ='DANH SÁCH'!F19 -> F12/16 Tổ 1 Ấp 6A X. Vĩnh Lộc A, H. Bình Chánh, TP. Hồ Chí Minh
A45: 3 | B45: ='DANH SÁCH'!C20 -> NGUYỄN THỊ DÒN | C45: ='DANH SÁCH'!D20 -> 27/09/1973 | D45: ='DANH SÁCH'!F20 -> Ấp 1 X. Tam Hiệp, H. Châu Thành, T. Tiền Giang
A46: 4 | B46: ='DANH SÁCH'!C21 -> NGUYỄN THIỀU KIỀU DUNG | C46: ='DANH SÁCH'!D21 -> 25/04/1998 | D46: ='DANH SÁCH'!F21 -> A3/42B/3 Tổ 2 Ấp 1A X. Vĩnh Lộc A, H. Bình Chánh, TP. Hồ Chí Minh
A47: 5 | B47: ='DANH SÁCH'!C22 -> NGUYỄN THỊ CÁC TƯỜNG | C47: ='DANH SÁCH'!D22 -> 26/03/2001 | D47: ='DANH SÁCH'!F22 -> Ấp 1 X. Tân Nghĩa, H. Cao Lãnh, T. Đồng Tháp
B49: Hạng xe: | C49: ….............. | D49: Từ ngày: | E49: ….................. | F49: đến ngày: | G49: …............
B50: Mã Khóa: | C50: …................................................ | E50: Xe: | F50: …..........................
A52: DANH SÁCH HỌC VIÊN
A54: STT | B54: Họ và tên | C54: Ngày sinh | D54: Nơi cư trú | E54: Số km thực hành | F54: Điểm thi kiểm tra cuối khóa | G54: Học viên ký tên
...

Sheet SH
A1: Ngày tháng | B1: Nội dung bài giảng | C1: Địa điểm | D1: Số Giờ Thực Hành | E1: Số Km thực hành | F1: Họ tên Hs vắng mặt | H1: Số nhiên liệu sử dụng | I1: Chữ ký
B2: (Thực hành hạng B số tự động) | F2: có lý do | G2: không có lý do | I2: Giáo Viên | J2: Trưởng
B3: Khóa : ….................................. | J3: Ban nghề
A4: 45300 | B4: Bài 1:Tập lái tại chỗ không nổ máy. | C4: Sân tập lái | D4: 5 | E4: 0 | H4: 0
A5: =A4 -> 45300 | B5: Bài 2: Tập lái tại chỗ có nổ máy. | C5: Sân tập lái | D5: 5 | E5: 0 | H5: =D5*2 -> 10
B6: Bài 3:Tập lái trong bãi phẳng . | C6: Sân tập lái | D6: 35 | E6: =D6*5 -> 175 | H6: =D6*2.5 -> 87.5
A7: =A5+1 -> 45301 | B7: - Tập lái đúng phần đường quy định. | D7: 10 | E7: =E6/D6*D7 -> 50 | H7: =D7*2.5 -> 25
A8: =A7+1 -> 45302 | B8: - Căn xe trên đường | D8: 10 | E8: =E7/D7*D8 -> 50 | H8: =D8*2.5 -> 25
A9: =A8+1 -> 45303 | B9: - Thay đổi số trên đường thẳng | D9: 10 | E9: =E8/D8*D9 -> 50 | H9: =D9*2.5 -> 25
A10: =A9+1 -> 45304 | D10: 5 | E10: =E9/D9*D10 -> 25 | H10: =D10*2.5 -> 12.5
B11: Bài 4: Tập lái trong hình số 3 và số 8 ghép, | C11: Sân tập lái | D11: 40 | E11: =D11*5 -> 200 | H11: =D11*2.5 -> 100
B12: tiến, lùi hình chữ chi
A13: =A10+1 -> 45305 | B13: - Tập lái xe trong hinh số 8 và số 3 | D13: 10 | E13: =D13*6 -> 60 | H13: =2.5*D13 -> 25
A14: =A13+1 -> 45306 | B14: - Tiến và lùi trong hình chữ chi | D14: 10 | E14: =D14*6 -> 60 | H14: =2.5*D14 -> 25 | K14: tổng km/xe | L14: =290*5 -> 1450
A15: =A14+1 -> 45307 | B15: - Tập lái trong hình số 3,8 ghép và hình chữ chi | D15: 10 | E15: =D15*6 -> 60 | H15: =2.5*D15 -> 25 | K15: 1hv/km/xe | L15: =L14/5 -> 290
A16: =A15+1 -> 45308 | B16: - Tập lái xe trong sa hình, ghép dọc, ghép ngang | D16: 10 | E16: =D16*6 -> 60 | H16: =2.5*D16 -> 25 | K16: giờ/xe | L16: =D22+D11+D6+D5+D4 -> 165
B17: Bài 5: Tập lái trên đường bằng | C17: Sân tập lái | D17: 40 | E17: 200 | H17: 100 | M17: Hạng B (STĐ) | N17: 1hv | O17: 5hv/1 xe
A18: =A16+1 -> 45309 | B18: - Tập lái theo đúng phần đường quy định | D18: 10 | E18: 50 | H18: 25 | M18: Bài 1:Tập lái tại chỗ không nổ máy. | N18: 1 | O18: 5 | P18: sa hình 41 giờ/1hv 205 giờ / 5hv/ 1 xe
A19: =A18+1 -> 45310 | B19: - Xử lý tình huống giao thông đơn giản | D19: 10 | E19: 50 | H19: 25 | M19: Bài 2: Tập lái tại chỗ có nổ máy. | N19: 1 | O19: 5
A20: =A19+1 -> 45311 | B20: - Dừng và đỗ xe đúng nơi quy định. | D20: 10 | E20: 50 | H20: 25 | M20: Bài 3:Tập lái trong bãi phẳng . | N20: 7 | O20: 35
A21: =A20+1 -> 45312 | D21: 10 | E21: 50 | H21: 25 | M21: Bài 4: Tập lái trong hình số 3 và số 8 ghép, | N21: 8 | O21: 40
B22: Bài 6: Bài tập lái xe tổng hợp | C22: Sân tập lái | D22: 80 | E22: 870 | H22: =80*2.5 -> 200 | M22: Bài 5: Tập lái trên đường bằng | N22: 8 | O22: 40
A23: =A16+1 -> 45309 | B23: - Lái xe trong hình các bài thi sát hạch GV hướng dẫn | D23: 10 | E23: =($E$22/80)*D23 -> 108.75 | H23: =D23*2.8 -> 28 | M23: Bài 6: Bài tập lái xe tổng hợp | N23: 16 | O23: 80
A24: =A23+1 -> 45310 | B24: - Học viên độc lập lái xe trên sa hình | D24: 10 | E24: =($E$22/80)*D24 -> 108.75 | H24: =D24*2.8 -> 28 | M24: Bài 07: Tập lái trên đường cao tốc và cao tốc phân kỳ đầu tư | N24: 6 | O24: 30 | P24: đường (DAT) 24 giờ/1hv 120 giờ/ 5hv /1 xe Thực hiện 50%
A25: =A24+1 -> 45311 | D25: 10 | E25: =($E$22/80)*D25 -> 108.75 | H25: =D25*2.8 -> 28 | M25: Bài 08:Tập lái trên đường đèo núi. | N25: 5 | O25: 25
A26: =A25+1 -> 45312 | D26: 10 | E26: =($E$22/80)*D26 -> 108.75 | H26: =D26*2.8 -> 28 | M26: Bài 09: Tập lái trên đường phức tạp | N26: 6 | O26: 30
A27: =A26+1 -> 45313 | D27: 10 | E27: =($E$22/80)*D27 -> 108.75 | H27: =D27*2.8 -> 28 | M27: Bài 10: Tập lái ban đêm | N27: 2 | O27: 10
A28: =A27+1 -> 45314 | D28: 10 | E28: =($E$22/80)*D28 -> 108.75 | H28: =D28*2.8 -> 28 | M28: Bài 11: Tập lái xe có tải | N28: 5 | O28: 25
A29: =A28+1 -> 45315 | D29: 10 | E29: =($E$22/80)*D29 -> 108.75 | H29: =D29*2.8 -> 28
A30: =A29+1 -> 45316 | D30: 10 | E30: =($E$22/80)*D30 -> 108.75 | H30: =D30*2.8 -> 28

Sheet IN SH
A1: Ngày tháng | B1: Nội dung bài giảng | C1: Địa điểm | D1: Số Giờ Thực Hành | E1: Số Km thực hành | F1: Họ tên Hs vắng mặt | H1: Số nhiên liệu sử dụng | I1: Chữ ký
B2: (Thực hành hạng B số tự động) | F2: có lý do | G2: không có lý do | I2: Giáo Viên | J2: Trưởng Ban nghề
B3: Khóa : …..................................
B4: Bài 1:Tập lái tại chỗ không nổ máy. | C4: Sân tập lái | D4: 5 | E4: 0 | H4: 0
B5: Bài 2: Tập lái tại chỗ có nổ máy. | C5: Sân tập lái | D5: 5 | E5: 0 | H5: =D5*2 -> 10
B6: Bài 3:Tập lái trong bãi phẳng . | C6: Sân tập lái | D6: 35 | E6: =D6*5 -> 175 | H6: =D6*2.5 -> 87.5
B7: - Tập lái đúng phần đường quy định.
B8: - Căn xe trên đường
B9: - Thay đổi số trên đường thẳng
B11: Bài 4: Tập lái trong hình số 3 và số 8 ghép, | C11: Sân tập lái | D11: 40 | E11: =D11*5 -> 200 | H11: =D11*2.5 -> 100
B12: tiến, lùi hình chữ chi
B13: - Tập lái xe trong hinh số 8 và số 3
B14: - Tiến và lùi trong hình chữ chi
B15: - Tập lái trong hình số 3,8 ghép và hình chữ chi
B16: - Tập lái xe trong sa hình, ghép dọc, ghép ngang
B17: Bài 5: Tập lái trên đường bằng | C17: Sân tập lái | D17: 40 | E17: 200 | H17: 100
B18: - Tập lái theo đúng phần đường quy định
B19: - Xử lý tình huống giao thông đơn giản
B20: - Dừng và đỗ xe đúng nơi quy định.
B22: Bài 6: Bài tập lái xe tổng hợp | C22: Sân tập lái | D22: 80 | E22: 870 | H22: =80*2.5 -> 200
B23: - Lái xe trong hình các bài thi sát hạch GV hướng dẫn
B24: - Học viên độc lập lái xe trên sa hình

Sheet LỊCH CABIN
A1: LỊCH CABIN HẠNG B11-K28-K29
A2: STT | B2: Họ và tên | C2: Ngày sinh | D2: Số CMND | E2: Nơi cư trú | F2: GV | G2: Khóa | H2: Ngày | I2: Giờ Tập | J2: Cabin
A3: 1 | I3: 07h00 - 10h00 | J3: 2
A4: 2 | I4: 10h20-13h20
A5: 3 | I5: 13h40-16h40
A6: 4 | I6: 17h00-20h00
A7: 5 | I7: 07h00 - 10h00 | J7: 3
A8: 6 | I8: 10h20-13h20
A9: 7 | I9: 13h40-16h40
A10: 8 | I10: 17h00-20h00
A11: 9 | I11: 07h00 - 10h00 | J11: 4
A12: 10 | I12: 10h20-13h20
A13: 11 | I13: 13h40-16h40
A14: 12 | I14: 17h00-20h00
A15: 13 | I15: 07h00 - 10h00 | J15: 1
A16: 14 | I16: 10h20-13h20
A17: 15 | I17: 13h40-16h40
A18: 16 | I18: 17h00-20h00
A19: 17 | I19: 07h00 - 10h00 | J19: 2
A20: 18 | I20: 10h20-13h20
A21: 19 | I21: 13h40-16h40
A22: 20 | I22: 17h00-20h00
A23: 21 | I23: 07h00 - 10h00 | J23: 3
A24: 22 | I24: 10h20-13h20
A25: 23 | I25: 13h40-16h40
A26: 24 | I26: 17h00-20h00
A27: 25 | I27: 07h00 - 10h00 | J27: 4
A28: 26 | I28: 10h20-13h20
A29: 27 | I29: 13h40-16h40
A30: 28 | I30: 17h00-20h00
A31: 29 | I31: 07h00 - 10h00 | J31: 1
A32: 30 | I32: 10h20-13h20
A33: 31 | I33: 13h40-16h40
A34: 32 | I34: 17h00-20h00
A35: 33 | I35: 07h00 - 10h00 | J35: 2
A36: 34 | I36: 10h20-13h20
A37: 35 | I37: 13h40-16h40
A38: 36 | I38: 17h00-20h00
A39: 37 | I39: 07h00 - 10h00 | J39: 3
A40: 38 | I40: 10h20-13h20
...

Sheet DAT
B1: Tên HV:.................................................................... | C1: Ngày sinh…......................... | F1: Xe…........................
A2: Ngày tháng | B2: Nội dung bài giảng | C2: Địa điểm | D2: Số Giờ Thực Hành | E2: Số Km thực hành | F2: Số nhiên liệu sử dụng | G2: Chữ ký
B3: (Thực hành hạng B số tự động) | G3: Giáo Viên | H3: Trưởng Ban nghề
B4: Khóa : …..................................
B5: Bài 07: Tập lái trên đường cao tốc và cao tốc phân kỳ đầu tư | C5: Ngoài đường
B6: - Di chuyển xe theo tốc độ quy định
B7: - Tốc độ phù hợp, thay đổi số phù hợp
B8: - Quan sát và xử lý khoảng cách an toàn
B9: - Phải tập trung, quan sát đúng huớng khi lái
B10: - Đảm bảo an toàn khi vào và ra cao tốc
B11: Bài 08:Tập lái trên đường dốc, đường vòng quanh co | C11: Ngoài đường
B12: - Tập lái xe căn lề trên đường, tập tắp lề
B13: - Phương pháp lái xe lên - xuống dốc
B14: - Di chuyển xe theo tốc độ quy định
B15: - Phán đoán, xử trí và thực hiện các biện pháp an toàn
B16: Bài 09: Tập lái trên đường phức tạp | C16: Ngoài đường
B17: - Tập lái qua khu vực đông xe qua lại
B18: - Tập lái xe qua khu vực đông dân cư
B19: - Lái xe qua những khúc cua che khất tầm nhìn
B20: - Qua ngã ba, ngã tư giao nhau,khu vực đường hẹp
B21: Bài 10: Tập lái ban đêm | C21: Ngoài đường | M21: 1 hv | N21: 5hv/1xe
B22: - Quan sát và xử lý khoảng cách an toàn | L22: Bài 07: Tập lái trên đường cao tốc và cao tốc phân kỳ đầu tư | M22: 6 | N22: 30
B23: - Di chuyển xe theo tốc độ quy định | L23: Bài 08:Tập lái trên đường dốc, đường vòng quanh co | M23: 5 | N23: 25
B24: - Phải tập trung, quan sát đúng huớng khi lái | L24: Bài 09: Tập lái trên đường phức tạp | M24: 6 | N24: 30
B25: - Phải sử dụng đèn pha, cốt hợp lý | L25: Bài 10: Tập lái ban đêm | M25: 2 | N25: 10
B26: - Đảm bảo an toàn khi rẽ trái hoặc phải | L26: Bài 11: Tập lái xe có tải | M26: 5 | N26: 25
B27: - Ước lượng khoảng cách khi xe đi ngược chiều | M27: 24 giờ | N27: =SUM(N22:N26) -> 120
B28: - Đi đúng phần đường
B29: - Phải lau chùi kính xe và chiếu hậu khi kiếng bị mờ
B30: - Tập đỗ xe và khởi hành
B31: Bài 11: Tập lái xe có tải | C31: Ngoài đường
B32: - Tốc độ phù hợp, chuyển số phù hợp
B33: - Phương pháp dừng và xuất phát khi có tải trọng
B34: - Quan sát và xử lý khoảng cách an toàn
B35: - Di chuyển xe theo tốc độ quy định
B36: - Đảm bảo an toàn khi rẽ trái hoặc phải
B37: Ôn thi tốt nghiệp
B38: Thi tốt nghiệp
B39: Ôn thi sát hạch
B40: Thi sát hạch
...
