Workbook

Sheet DANH SÁCH
A1: STT | B1: Họ và tên | C1: Ngày sinh | D1: Số CMND/HC | E1: Địa chỉ thường trú | F1: GV
A2: 1 | B2: DIỆP LƯƠNG AN | C2: 34335 | D2: 75094004469 | E2: Tổ 5 Ấp 2 X. Thanh Sơn, H. Định Quán, T. Đồng Nai | F2: C BÌNH
A3: 2 | B3: ĐẶNG VĂN ĐEN | C3: 33604 | D3: 96092000050 | E3: 21/23/6 Đất Thánh P.06, Q. Tân Bình, TP. Hồ Chí Minh | F3: C BÌNH
A4: 3 | B4: LÝ HUỲNH ĐỨC DUY | C4: 37270 | D4: 79202018011 | E4: 167 Nguyễn Văn Công P.03, Q. Gò Vấp, TP. Hồ Chí Minh | F4: HIỀN
A5: 4 | B5: HỒ TUẤN KIỆT | C5: 36296 | D5: 79099031671 | E5: 250/25/15 Nguyễn Thượng Hiền P.05, Q. Phú Nhuận, TP. Hồ Chí Minh | F5: C BÌNH
A6: 5 | B6: TRẦN HỮU LONG | C6: 33170 | D6: 60090015429 | E6: Ấp Giồng Lớn X. Mỹ Hạnh Nam, H. Đức Hòa, T. Long An | F6: C BÌNH
A7: 6 | B7: PHẠM VĂN PHÚ | C7: 36552 | D7: 79200016370 | E7: Số 337 Bình Mỹ Ấp 6B X. Bình Mỹ, H. Củ Chi, TP. Hồ Chí Minh | F7: NGA
A8: 7 | B8: ĐỖ HỮU PHƯỚC | C8: 30909 | D8: 79084005411 | E8: 03 Nguyễn Văn Ngọc P. Tân Thành, Q. Tân Phú, TP. Hồ Chí Minh | F8: C BÌNH
A9: 8 | B9: ĐINH THANH TOÀN | C9: 37769 | D9: 86203008924 | E9: Ấp 4 X. Tân An Luông, H. Vũng Liêm, T. Vĩnh Long | F9: CHỈNH
A10: 9
A11: 10
A12: 11
A13: 12
A14: 13
A15: 14
A16: 15
A17: 16
A18: 17
A19: 18
A20: 19
A21: 20
... A31: 30

Sheet DANH SÁCH CHIA NHÓM
A1: HẠNG | C1: D | D1: KHÓA | E1: 79029K25C….. | H1: TÊN KHÓA | I1: K…
A2: Nhóm | B2: STT | C2: Họ và tên | D2: Ngày sinh | E2: Số CMND | F2: Nơi cư trú | H2: GV | I2: SỐ XE | K2: STT | L2: GVKH | M2: Xe KH | N2: Hạn giấy phép xe tập lái
A3: 1 | B3: 1 | C3: DIỆP LƯƠNG AN | D3: 34335 | E3: 75094004469 | F3: Tổ 5 Ấp 2 X. Thanh Sơn, H. Định Quán, T. Đồng Nai | G3: C BÌNH | H3: PHẠM VĂN ĐẶNG | I3: 51C-63517 | K3: 1
B4: 2 | C4: ĐẶNG VĂN ĐEN | D4: 33604 | E4: 96092000050 | F4: 21/23/6 Đất Thánh P.06, Q. Tân Bình, TP. Hồ Chí Minh | G4: C BÌNH | K4: 2
B5: 3 | C5: LÝ HUỲNH ĐỨC DUY | D5: 37270 | E5: 79202018011 | F5: 167 Nguyễn Văn Công P.03, Q. Gò Vấp, TP. Hồ Chí Minh | G5: HIỀN | K5: 3
B6: 4 | C6: HỒ TUẤN KIỆT | D6: 36296 | E6: 79099031671 | F6: 250/25/15 Nguyễn Thượng Hiền P.05, Q. Phú Nhuận, TP. Hồ Chí Minh | G6: C BÌNH | K6: 4
B7: 5 | C7: TRẦN HỮU LONG | D7: 33170 | E7: 60090015429 | F7: Ấp Giồng Lớn X. Mỹ Hạnh Nam, H. Đức Hòa, T. Long An | G7: C BÌNH
B8: 6 | C8: PHẠM VĂN PHÚ | D8: 36552 | E8: 79200016370 | F8: Số 337 Bình Mỹ Ấp 6B X. Bình Mỹ, H. Củ Chi, TP. Hồ Chí Minh | G8: NGA
B9: 7 | C9: ĐỖ HỮU PHƯỚC | D9: 30909 | E9: 79084005411 | F9: 03 Nguyễn Văn Ngọc P. Tân Thành, Q. Tân Phú, TP. Hồ Chí Minh | G9: C BÌNH
B10: 8 | C10: ĐINH THANH TOÀN | D10: 37769 | E10: 86203008924 | F10: Ấp 4 X. Tân An Luông, H. Vũng Liêm, T. Vĩnh Long | G10: CHỈNH
A11: 2 | B11: 1
B12: 2
B13: 3
B14: 4
B15: 5
B16: 6
B17: 7
B18: 8
A19: 3 | B19: 1
B20: 2
B21: 3
B22: 4
B23: 5
B24: 6
B25: 7
B26: 8
A27: 4 | B27: 1
B28: 2
B29: 3
B30: 4
B31: 5
B32: 6
B33: 7
B34: 8

Sheet BÌA THEO DÕI
C3: TRUNG TÂM GIÁO DỤC NGHỀ NGHIỆP TIẾN THÀNH
E5: SỔ THEO DÕI THỰC HÀNH LÁI XE
C10: Họ và tên giáo viên: | F10: …..................................................................
C11: Biển số xe tập lái số: | F11: …..................................................................
C13: Mã khóa: | E13: …......................................... | H13: Tên khóa: | J13: ….......... | K13: Hạng: | L13: C1-C
C18: Năm 2025

Sheet SỔ THEO DÕI
B1: Hạng xe: | C1: ….............. | D1: Từ ngày: | E1: ….................. | F1: đến ngày: | G1: …............
B2: Mã Khóa: | C2: …................................................ | E2: Xe: | F2: …..........................
A4: DANH SÁCH HỌC VIÊN
A6: STT | B6: Họ và tên | C6: Ngày sinh | D6: Nơi cư trú | E6: Số km thực hành | F6: Điểm thi kiểm tra cuối khóa | G6: Học viên ký tên
A7: 1 | B7: ='DANH SÁCH CHIA NHÓM'!C3 -> DIỆP LƯƠNG AN | C7: ='DANH SÁCH CHIA NHÓM'!D3 -> 34335 | D7: ='DANH SÁCH CHIA NHÓM'!F3 -> Tổ 5 Ấp 2 X. Thanh Sơn, H. Định Quán, T. Đồng Nai
A8: 2 | B8: ='DANH SÁCH CHIA NHÓM'!C4 -> ĐẶNG VĂN ĐEN | C8: ='DANH SÁCH CHIA NHÓM'!D4 -> 33604 | D8: ='DANH SÁCH CHIA NHÓM'!F4 -> 21/23/6 Đất Thánh P.06, Q. Tân Bình, TP. Hồ Chí Minh
A9: 3 | B9: ='DANH SÁCH CHIA NHÓM'!C5 -> LÝ HUỲNH ĐỨC DUY | C9: ='DANH SÁCH CHIA NHÓM'!D5 -> 37270 | D9: ='DANH SÁCH CHIA NHÓM'!F5 -> 167 Nguyễn Văn Công P.03, Q. Gò Vấp, TP. Hồ Chí Minh
A10: 4 | B10: ='DANH SÁCH CHIA NHÓM'!C6 -> HỒ TUẤN KIỆT | C10: ='DANH SÁCH CHIA NHÓM'!D6 -> 36296 | D10: ='DANH SÁCH CHIA NHÓM'!F6 -> 250/25/15 Nguyễn Thượng Hiền P.05, Q. Phú Nhuận, TP. Hồ Chí Minh
A11: 5 | B11: ='DANH SÁCH CHIA NHÓM'!C7 -> TRẦN HỮU LONG | C11: ='DANH SÁCH CHIA NHÓM'!D7 -> 33170 | D11: ='DANH SÁCH CHIA NHÓM'!F7 -> Ấp Giồng Lớn X. Mỹ Hạnh Nam, H. Đức Hòa, T. Long An
A12: 6 | B12: ='DANH SÁCH CHIA NHÓM'!C8 -> PHẠM VĂN PHÚ | C12: ='DANH SÁCH CHIA NHÓM'!D8 -> 36552 | D12: ='DANH SÁCH CHIA NHÓM'!F8 -> Số 337 Bình Mỹ Ấp 6B X. Bình Mỹ, H. Củ Chi, TP. Hồ Chí Minh
A13: 7 | B13: ='DANH SÁCH CHIA NHÓM'!C9 -> ĐỖ HỮU PHƯỚC | C13: ='DANH SÁCH CHIA NHÓM'!D9 -> 30909 | D13: ='DANH SÁCH CHIA NHÓM'!F9 -> 03 Nguyễn Văn Ngọc P. Tân Thành, Q. Tân Phú, TP. Hồ Chí Minh
A14: 8 | B14: ='DANH SÁCH CHIA NHÓM'!C10 -> ĐINH THANH TOÀN | C14: ='DANH SÁCH CHIA NHÓM'!D10 -> 37769 | D14: ='DANH SÁCH CHIA NHÓM'!F10 -> Ấp 4 X. Tân An Luông, H. Vũng Liêm, T. Vĩnh Long
B17: Hạng xe: | C17: ….............. | D17: Từ ngày: | E17: ….................. | F17: đến ngày: | G17: …............
B18: Mã Khóa: | C18: …................................................ | E18: Xe: | F18: …..........................
A20: DANH SÁCH HỌC VIÊN
A22: STT | B22: Họ và tên | C22: Ngày sinh | D22: Nơi cư trú | E22: Số km thực hành | F22: Điểm thi kiểm tra cuối khóa | G22: Học viên ký tên
A23: 1 | B23: ='DANH SÁCH CHIA NHÓM'!C11 -> 0 | C23: ='DANH SÁCH CHIA NHÓM'!D11 -> 0 | D23: ='DANH SÁCH CHIA NHÓM'!F11 -> 0
A24: 2 | B24: ='DANH SÁCH CHIA NHÓM'!C12 -> 0 | C24: ='DANH SÁCH CHIA NHÓM'!D12 -> 0 | D24: ='DANH SÁCH CHIA NHÓM'!F12 -> 0
A25: 3 | B25: ='DANH SÁCH CHIA NHÓM'!C13 -> 0 | C25: ='DANH SÁCH CHIA NHÓM'!D13 -> 0 | D25: ='DANH SÁCH CHIA NHÓM'!F13 -> 0
A26: 4 | B26: ='DANH SÁCH CHIA NHÓM'!C14 -> 0 | C26: ='DANH SÁCH CHIA NHÓM'!D14 -> 0 | D26: ='DANH SÁCH CHIA NHÓM'!F14 -> 0
A27: 5 | B27: ='DANH SÁCH CHIA NHÓM'!C15 -> 0 | C27: ='DANH SÁCH CHIA NHÓM'!D15 -> 0 | D27: ='DANH SÁCH CHIA NHÓM'!F15 -> 0
A28: 6 | B28: ='DANH SÁCH CHIA NHÓM'!C16 -> 0 | C28: ='DANH SÁCH CHIA NHÓM'!D16 -> 0 | D28: ='DANH SÁCH CHIA NHÓM'!F16 -> 0
A29: 7 | B29: ='DANH SÁCH CHIA NHÓM'!C17 -> 0 | C29: ='DANH SÁCH CHIA NHÓM'!D17 -> 0 | D29: ='DANH SÁCH CHIA NHÓM'!F17 -> 0
A30: 8 | B30: ='DANH SÁCH CHIA NHÓM'!C18 -> 0 | C30: ='DANH SÁCH CHIA NHÓM'!D18 -> 0 | D30: ='DANH SÁCH CHIA NHÓM'!F18 -> 0
B32: Hạng xe: | C32: ….............. | D32: Từ ngày: | E32: ….................. | F32: đến ngày: | G32: …............
B33: Mã Khóa: | C33: …................................................ | E33: Xe: | F33: …..........................
A35: DANH SÁCH HỌC VIÊN
A37: STT | B37: Họ và tên | C37: Ngày sinh | D37: Nơi cư trú | E37: Số km thực hành | F37: Điểm thi kiểm tra cuối khóa | G37: Học viên ký tên
A38: 1 | B38: ='DANH SÁCH CHIA NHÓM'!C19 -> 0 | C38: ='DANH SÁCH CHIA NHÓM'!D19 -> 0 | D38: ='DANH SÁCH CHIA NHÓM'!F19 -> 0
A39: 2 | B39: ='DANH SÁCH CHIA NHÓM'!C20 -> 0 | C39: ='DANH SÁCH CHIA NHÓM'!D20 -> 0 | D39: ='DANH SÁCH CHIA NHÓM'!F20 -> 0
A40: 3 | B40: ='DANH SÁCH CHIA NHÓM'!C21 -> 0 | C40: ='DANH SÁCH CHIA NHÓM'!D21 -> 0 | D40: ='DANH SÁCH CHIA NHÓM'!F21 -> 0
A41: 4 | B41: ='DANH SÁCH CHIA NHÓM'!C22 -> 0 | C41: ='DANH SÁCH CHIA NHÓM'!D22 -> 0 | D41: ='DANH SÁCH CHIA NHÓM'!F22 -> 0
A42: 5 | B42: ='DANH SÁCH CHIA NHÓM'!C23 -> 0 | C42: ='DANH SÁCH CHIA NHÓM'!D23 -> 0 | D42: ='DANH SÁCH CHIA NHÓM'!F23 -> 0
A43: 6 | B43: ='DANH SÁCH CHIA NHÓM'!C24 -> 0 | C43: ='DANH SÁCH CHIA NHÓM'!D24 -> 0 | D43: ='DANH SÁCH CHIA NHÓM'!F24 -> 0
A44: 7 | B44: ='DANH SÁCH CHIA NHÓM'!C25 -> 0 | C44: ='DANH SÁCH CHIA NHÓM'!D25 -> 0 | D44: ='DANH SÁCH CHIA NHÓM'!F25 -> 0
A45: 8 | B45: ='DANH SÁCH CHIA NHÓM'!C26 -> 0 | C45: ='DANH SÁCH CHIA NHÓM'!D26 -> 0 | D45: ='DANH SÁCH CHIA NHÓM'!F26 -> 0
B47: Hạng xe: | C47: ….............. | D47: Từ ngày: | E47: ….................. | F47: đến ngày: | G47: …............
B48: Mã Khóa: | C48: …................................................ | E48: Xe: | F48: …..........................
A50: DANH SÁCH HỌC VIÊN
A52: STT | B52: Họ và tên | C52: Ngày sinh | D52: Nơi cư trú | E52: Số km thực hành | F52: Điểm thi kiểm tra cuối khóa | G52: Học viên ký tên
...

Sheet SA HÌNH
A1: Ngày tháng | B1: Nội dung bài giảng | C1: Địa điểm | D1: Số Giờ Thực Hành | E1: Số Km thực hành | F1: Họ tên Hs vắng mặt | H1: Số nhiên liệu sử dụng | I1: Chữ ký
B2: (Thực hành hạng C1-C) | F2: có lý do | G2: không có lý do | I2: Giáo Viên | J2: Trưởng Ban nghề
B3: Khóa : ….................................. | L3: hạng C1-C | M3: giờ | O3: km
A4: 45658 | B4: Bài 1:Tập lái trong bãi phẳng . | C4: Sân tập lái | D4: 4 | E4: 12 | H4: =D4*1.4 -> 5.6 | L4: Tập lái trong bãi phẳng . | M4: 4 | N4: 4/1hv 32h/8hv | O4: 12 | P4: 15km/1hv 120km/8hv
B5: - Khởi hành và dừng xe đúng quy trình | L5: Tập lái xe trong hình số 3, số 8 ghép; tiến lùi theo hình chữ chi | M5: 4 | O5: 12
B6: - Thay đổi số trên đường thẳng | L6: Tập lái xe trên đường bằng | M6: 4 | O6: 12
A7: =A4 -> 45658 | B7: Bài 2: Tập lái xe trong hình số 3, số 8 ghép; tiến lùi theo hình chữ chi | D7: 4 | E7: 12 | H7: =D7*1.4 -> 5.6 | L7: Bài tập lái xe tổng hợp | M7: 20 | O7: 84
B8: - Tập lái xe trong hinh số 3 | L8: Tập lái xe trên đường dốc, đường vòng quanh co | M8: 10 | N8: 5h/1hv 40h/8hv Thực hiện 50% | O8: 105km/1hv=840km/10hv
B9: - Tập lái xe trong hinh số 8 | L9: Tập lái xe trên đường phức tạp | M9: 12
B10: - Tiến và lùi trong hình chữ chi | L10: Tập lái xe ban đêm | M10: 8
A11: =A7+1 -> 45659 | B11: Bài 3: Tập lái xe trên đường bằng | C11: Sân tập lái | D11: 4 | E11: 12 | H11: =D11*1.4 -> 5.6 | L11: Tập lái xe có tải | M11: 10
B12: - Dừng và đỗ xe đúng nơi quy định.
B13: - Di chuyển xe theo tốc độ quy định
B14: Bài 4: Bài tập lái xe tổng hợp | C14: Sân tập lái | D14: 20 | E14: 84 | H14: =D14*1.8 -> 36
A15: =A11+1 -> 45660 | B15: - Lái xe trong hình các bài thi sát hạch GV hướng dẫn | D15: 10 | E15: 42 | H15: =D15*1.8 -> 18
A16: =A15+1 -> 45661 | B16: - Học viên độc lập lái xe trên sa hình | D16: 10 | E16: 42 | H16: =D16*1.8 -> 18

Sheet MẪU IN SA HÌNH
A1: Ngày tháng | B1: Nội dung bài giảng | C1: Địa điểm | D1: Số Giờ Thực Hành | E1: Số Km thực hành | F1: Họ tên Hs vắng mặt | H1: Số nhiên liệu sử dụng | I1: Chữ ký
B2: (Thực hành hạng C1-C) | F2: có lý do | G2: không có lý do | I2: Giáo Viên | J2: Trưởng Ban nghề
B3: Khóa : …..................................
B4: Bài 1:Tập lái trong bãi phẳng . | C4: Sân tập lái | D4: 4 | E4: 12 | H4: =D4*1.4 -> 5.6
B5: - Khởi hành và dừng xe đúng quy trình
B6: - Thay đổi số trên đường thẳng
B7: Bài 2: Tập lái xe trong hình số 3, số 8 ghép; tiến lùi theo hình chữ chi | D7: 4 | E7: 12 | H7: =D7*1.4 -> 5.6
B8: - Tập lái xe trong hinh số 3
B9: - Tập lái xe trong hinh số 8
B10: - Tiến và lùi trong hình chữ chi
B11: Bài 3: Tập lái xe trên đường bằng | C11: Sân tập lái | D11: 4 | E11: 12 | H11: =D11*1.4 -> 5.6
B12: - Dừng và đỗ xe đúng nơi quy định.
B13: - Di chuyển xe theo tốc độ quy định
B14: Bài 4: Bài tập lái xe tổng hợp | C14: Sân tập lái | D14: 20 | E14: 84 | H14: =D14*1.8 -> 36
B15: - Lái xe trong hình các bài thi sát hạch GV hướng dẫn
B16: - Học viên độc lập lái xe trên sa hình

Sheet MẪU IN ĐƯỜNG TRƯỜNG
B1: Tên HV:.................................................................... | C1: Ngày sinh…......................... | F1: Xe…........................
A2: Ngày tháng | B2: Nội dung bài giảng | C2: Địa điểm | D2: Số Giờ Thực Hành | E2: Số Km thực hành | F2: Số nhiên liệu sử dụng | G2: Chữ ký
B3: (Thực hành hạng C1-C) | G3: Giáo Viên | H3: Trưởng Ban nghề
B4: Khóa : …..................................
B5: Bài 5: Tập lái xe trên đường dốc, đường vòng quanh co | C5: Ngoài đường Tuyến đường quy định
B6: - Di chuyển xe theo tốc độ quy định
B7: - Tập lái xe căn lề trên đường, tập tắp lề
B8: - Phán đoán, xử trí và thực hiện các biện pháp an toàn
B9: Bài 6: Tập lái trên đường phức tạp | C9: Ngoài đường Tuyến đường quy định
B10: - Xử lý tình huống trên đường
B11: - Vòng tránh khi xe vào đường xấu.
B12: - Qua ngã ba, ngã tư giao nhau,khu vực đường hẹp
B13: Bài 7: Tập lái ban đêm | C13: Ngoài đường Tuyến đường quy định
B14: - Quan sát và xử lý khoảng cách an toàn
B15: - Di chuyển xe theo tốc độ quy định
B16: - Phải tập trung, quan sát đúng huớng khi lái
B17: - Đảm bảo an toàn khi rẽ trái hoặc phải
B18: - Độc lập điều khiển xe trên đường vào ban đêm
B19: Bài 8: Tập lái xe có tải | C19: Ngoài đường Tuyến đường quy định
B20: - Tốc độ phù hợp, chuyển số phù hợp với tải trọng
B21: - Phải tập trung, quan sát đúng huớng khi lái
B22: - Quan sát và xử lý khoảng cách an toàn
B23: - Vòng tránh khi xe có tải trọng
B24: Ôn thi tốt nghiệp
B25: Thi tốt nghiệp
B26: Ôn thi sát hạch
B27: Thi sát hạch
B28: Nhận xét của Giáo Viên :
B29: ........................................................................................................................................................................................................
B30: ........................................................................................................................................................................................................
F31: Giáo Viên Ký tên
