Workbook

Sheet ds-gv
A1: STT | B1: Họ và tên | C1: Ngày sinh | D1: Số CMND/HC | E1: Địa chỉ thường trú | F1: GV
A2: 1
A3: 2
A4: 3
A5: 4
A6: 5
A7: 6
A8: 7
A9: 8
A10: 9
A11: 10
A12: 11
A13: 12
... A81: 80

Sheet DANH SÁCH
A1: HẠNG | C1: B2 | D1: KHÓA | E1: 79029K25B2003 | G1: TÊN KHÓA | I1: K03
A2: Nhóm | B2: STT | C2: Họ và tên | D2: Ngày sinh | E2: Số CMND | F2: Nơi cư trú | H2: GV SỐ SÀN | I2: SỐ XE (CHỦ XE) | J2: SỐ XE TĐ (GV TĐ) | K2: STT | L2: GVKH | M2: Xe KH | N2: CHỦ XE | O2: Hạn giấy phép xe tập lái
A3: 1 | B3: 1 | K3: 1
B4: 2 | K4: 2
B5: 3 | K5: 3
B6: 4 | K6: 4
B7: 5 | K7: 5
A8: 2 | B8: 1 | K8: 6
B9: 2 | K9: 7
B10: 3 | K10: 8
B11: 4 | K11: 9
B12: 5 | K12: 10
A13: 3 | B13: 1 | K13: 11
B14: 2 | K14: 12
B15: 3 | K15: 13
B16: 4 | K16: 14
B17: 5 | K17: 15
A18: 4 | B18: 1 | K18: 16
B19: 2 | K19: 17
B20: 3 | K20: 18
B21: 4 | K21: 19
B22: 5 | K22: 20
A23: 5 | B23: 1 | K23: 21
B24: 2 | K24: 22
B25: 3 | K25: 23
B26: 4 | K26: 24
B27: 5
A28: 6 | B28: 1
B29: 2
B30: 3
B31: 4
B32: 5
A33: 7 | B33: 1
B34: 2
B35: 3
B36: 4
B37: 5
A38: 8 | B38: 1
B39: 2
B40: 3
...

Sheet BÌA
C2: TRUNG TÂM GIÁO DỤC NGHỀ NGHIỆP TIẾN THÀNH
E5: SỔ THEO DÕI THỰC HÀNH LÁI XE
C10: Họ và tên giáo viên: | G10: ….......................................................
C11: Họ và tên giáo viên số tự động: | G11: ….......................................................
C13: Biển số xe tập lái số sàn: | G13: ….......................................................
C14: Biển số xe tập lái số tự động: | G14: ….......................................................
C16: Mã khóa: | E16: ................................... | H16: Tên khóa: | J16: …....... | K16: Hạng: | L16: ….......
C18: Năm 202…

Sheet SỔ THEO DÕI
B1: Hạng xe: | C1: …................ | D1: Từ ngày: | E1: ….................. | F1: đến ngày: | G1: …............
B2: Khóa: | C2: …................................................................................................ | E2: Xe: | F2: ….........................
A4: DANH SÁCH HỌC VIÊN
A6: STT | B6: Họ và tên | C6: Ngày sinh | D6: Nơi cư trú | E6: Số km thực hành | F6: Điểm thi kiểm tra cuối khóa | G6: Học viên ký tên
A7: 1 | B7: ='DANH SÁCH'!C3 -> 0 | C7: ='DANH SÁCH'!D3 -> 0 | D7: ='DANH SÁCH'!F3 -> 0
A8: 2 | B8: ='DANH SÁCH'!C4 -> 0 | C8: ='DANH SÁCH'!D4 -> 0 | D8: ='DANH SÁCH'!F4 -> 0
A9: 3 | B9: ='DANH SÁCH'!C5 -> 0 | C9: ='DANH SÁCH'!D5 -> 0 | D9: ='DANH SÁCH'!F5 -> 0
A10: 4 | B10: ='DANH SÁCH'!C6 -> 0 | C10: ='DANH SÁCH'!D6 -> 0 | D10: ='DANH SÁCH'!F6 -> 0
A11: 5 | B11: ='DANH SÁCH'!C7 -> 0 | C11: ='DANH SÁCH'!D7 -> 0 | D11: ='DANH SÁCH'!F7 -> 0
B13: Hạng xe: | C13: …................ | D13: Từ ngày: | E13: ….................. | F13: đến ngày: | G13: …............
B14: Khóa: | C14: …................................................................................................ | E14: Xe: | F14: ….........................
A16: DANH SÁCH HỌC VIÊN
A18: STT | B18: Họ và tên | C18: Ngày sinh | D18: Nơi cư trú | E18: Số km thực hành | F18: Điểm thi kiểm tra cuối khóa | G18: Học viên ký tên
A19: 1 | B19: ='DANH SÁCH'!C8 -> 0 | C19: ='DANH SÁCH'!D8 -> 0 | D19: ='DANH SÁCH'!F8 -> 0
A20: 2 | B20: ='DANH SÁCH'!C9 -> 0 | C20: ='DANH SÁCH'!D9 -> 0 | D20: ='DANH SÁCH'!F9 -> 0
A21: 3 | B21: ='DANH SÁCH'!C10 -> 0 | C21: ='DANH SÁCH'!D10 -> 0 | D21: ='DANH SÁCH'!F10 -> 0
A22: 4 | B22: ='DANH SÁCH'!C11 -> 0 | C22: ='DANH SÁCH'!D11 -> 0 | D22: ='DANH SÁCH'!F11 -> 0
A23: 5 | B23: ='DANH SÁCH'!C12 -> 0 | C23: ='DANH SÁCH'!D12 -> 0 | D23: ='DANH SÁCH'!F12 -> 0
B25: Hạng xe: | C25: …................ | D25: Từ ngày: | E25: ….................. | F25: đến ngày: | G25: …............
B26: Khóa: | C26: …................................................................................................ | E26: Xe: | F26: ….........................
A28: DANH SÁCH HỌC VIÊN
A30: STT | B30: Họ và tên | C30: Ngày sinh | D30: Nơi cư trú | E30: Số km thực hành | F30: Điểm thi kiểm tra cuối khóa | G30: Học viên ký tên
A31: 1 | B31: ='DANH SÁCH'!C13 -> 0 | C31: ='DANH SÁCH'!D13 -> 0 | D31: ='DANH SÁCH'!F13 -> 0
A32: 2 | B32: ='DANH SÁCH'!C14 -> 0 | C32: ='DANH SÁCH'!D14 -> 0 | D32: ='DANH SÁCH'!F14 -> 0
A33: 3 | B33: ='DANH SÁCH'!C15 -> 0 | C33: ='DANH SÁCH'!D15 -> 0 | D33: ='DANH SÁCH'!F15 -> 0
A34: 4 | B34: ='DANH SÁCH'!C16 -> 0 | C34: ='DANH SÁCH'!D16 -> 0 | D34: ='DANH SÁCH'!F16 -> 0
A35: 5 | B35: ='DANH SÁCH'!C17 -> 0 | C35: ='DANH SÁCH'!D17 -> 0 | D35: ='DANH SÁCH'!F17 -> 0
B37: Hạng xe: | C37: …................ | D37: Từ ngày: | E37: ….................. | F37: đến ngày: | G37: …............
B38: Khóa: | C38: …................................................................................................ | E38: Xe: | F38: ….........................
A40: DANH SÁCH HỌC VIÊN
A42: STT | B42: Họ và tên | C42: Ngày sinh | D42: Nơi cư trú | E42: Số km thực hành | F42: Điểm thi kiểm tra cuối khóa | G42: Học viên ký tên
A43: 1 | B43: ='DANH SÁCH'!C18 -> 0 | C43: ='DANH SÁCH'!D18 -> 0 | D43: ='DANH SÁCH'!F18 -> 0
A44: 2 | B44: ='DANH SÁCH'!C19 -> 0 | C44: ='DANH SÁCH'!D19 -> 0 | D44: ='DANH SÁCH'!F19 -> 0
A45: 3 | B45: ='DANH SÁCH'!C20 -> 0 | C45: ='DANH SÁCH'!D20 -> 0 | D45: ='DANH SÁCH'!F20 -> 0
A46: 4 | B46: ='DANH SÁCH'!C21 -> 0 | C46: ='DANH SÁCH'!D21 -> 0 | D46: ='DANH SÁCH'!F21 -> 0
A47: 5 | B47: ='DANH SÁCH'!C22 -> 0 | C47: ='DANH SÁCH'!D22 -> 0 | D47: ='DANH SÁCH'!F22 -> 0
B49: Hạng xe: | C49: …................ | D49: Từ ngày: | E49: ….................. | F49: đến ngày: | G49: …............
B50: Khóa: | C50: …................................................................................................ | E50: Xe: | F50: ….........................
A52: DANH SÁCH HỌC VIÊN
A54: STT | B54: Họ và tên | C54: Ngày sinh | D54: Nơi cư trú | E54: Số km thực hành | F54: Điểm thi kiểm tra cuối khóa | G54: Học viên ký tên
...

Sheet PHÂN NGÀY SH
A1: Ngày tháng | B1: Nội dung bài giảng | C1: Địa điểm | D1: Số Giờ Thực Hành | E1: Số Km thực hành | F1: Họ tên Hs vắng mặt | H1: Số nhiên liệu sử dụng | I1: Chữ ký
B2: (Thực hành hạng B - số sàn) | F2: có lý do | G2: không có lý do | I2: Giáo Viên | J2: Trưởng Ban nghề
B3: Khóa : …..................................
A4: 45728 | B4: Bài 1:Tập lái tại chỗ không nổ máy. | C4: Sân tập lái | D4: 5 | E4: 0 | H4: 0
A5: =A4 -> 45728 | B5: Bài 2: Tập lái tại chỗ có nổ máy. | C5: Sân tập lái | D5: 5 | E5: 0 | H5: 8
B6: Bài 3:Tập lái trong bãi phẳng . | C6: Sân tập lái | D6: 40 | E6: 200 | H6: 100
A7: =A5+1 -> 45729 | B7: - Tập lái đúng phần đường quy định. | D7: 10 | E7: 50 | H7: 25
A8: =A7+1 -> 45730 | B8: - Căn xe trên đường | D8: 10 | E8: 50 | H8: 25
A9: =A8+1 -> 45731 | B9: - Thay đổi số trên đường thẳng | D9: 10 | E9: 50 | H9: 25
A10: =A9+1 -> 45732 | D10: 10 | E10: 50 | H10: 25
B11: Bài 4: Tập lái trong hình số 3 và số 8 ghép, | C11: Sân tập lái | D11: 40 | E11: 200 | H11: 100
B12: tiến, lùi hình chữ chi
A13: =A10+1 -> 45733 | B13: - Tập lái xe trong hinh số 8 và số 3 | D13: 10 | E13: 50 | H13: 25
A14: =A13+1 -> 45734 | B14: - Tiến và lùi trong hình chữ chi | D14: 10 | E14: 50 | H14: 25
A15: =A14+1 -> 45735 | B15: - Tập lái trong hình số 3,8 ghép và hình chữ chi | D15: 10 | E15: 50 | H15: 25
A16: =A15+1 -> 45736 | D16: 10 | E16: 50 | H16: 25
B17: Bài 5: Tập lái trên đường bằng | C17: Sân tập lái | D17: 40 | E17: 200 | H17: 100
A18: =A16+1 -> 45737 | B18: - Tập lái theo đúng phần đường quy định | D18: 10 | E18: 50 | H18: 25
A19: =A18+1 -> 45738 | B19: - Xử lý tình huống giao thông đơn giản | D19: 10 | E19: 50 | H19: 25
A20: =A19+1 -> 45739 | B20: - Dừng và đỗ xe đúng nơi quy định. | D20: 10 | E20: 50 | H20: 25
A21: =A20+1 -> 45740 | D21: 10 | E21: 50 | H21: 25
B22: Bài 6.: Bài tập lái xe tổng hợp | C22: Sân tập lái | D22: 75 | E22: 850 | H22: =E22*0.24 -> 204
A23: =A21+1 -> 45741 | B23: - Lái xe trong hình các bài thi sát hạch GV hướng dẫn | D23: 10 | E23: =E22/D22*D23 -> 113.33333 | H23: =E23*0.24 -> 27.2
A24: =A23+1 -> 45742 | B24: - Học viên độc lập lái xe trên sa hình | D24: 10 | E24: =E23/D23*D24 -> 113.33333 | H24: =E24*0.24 -> 27.2
A25: =A24+1 -> 45743 | D25: 10 | E25: =E24/D24*D25 -> 113.33333 | H25: =E25*0.24 -> 27.2
A26: =A25+1 -> 45744 | D26: 10 | E26: =E25/D25*D26 -> 113.33333 | H26: =E26*0.24 -> 27.2
A27: =A26+1 -> 45745 | D27: 10 | E27: =E26/D26*D27 -> 113.33333 | H27: =E27*0.24 -> 27.2
A28: =A27+1 -> 45746 | D28: 10 | E28: =E27/D27*D28 -> 113.33333 | H28: =E28*0.24 -> 27.2
A29: =A28+1 -> 45747 | D29: 10 | E29: =E28/D28*D29 -> 113.33333 | H29: =E29*0.24 -> 27.2
A30: =A29+1 -> 45748 | D30: 5 | E30: =E29/D29*D30 -> 56.666667 | H30: =E30*0.24 -> 13.6

Sheet IN SH
A1: Ngày tháng | B1: Nội dung bài giảng | C1: Địa điểm | D1: Số Giờ Thực Hành | E1: Số Km thực hành | F1: Họ tên Hs vắng mặt | H1: Số nhiên liệu sử dụng | I1: Chữ ký
B2: (Thực hành hạng B - số sàn) | F2: có lý do | G2: không có lý do | I2: Giáo Viên | J2: Trưởng Ban nghề
B3: Khóa : …..................................
B4: Bài 1:Tập lái tại chỗ không nổ máy. | C4: Sân tập lái | D4: 5 | E4: 0 | H4: 0
B5: Bài 2: Tập lái tại chỗ có nổ máy. | C5: Sân tập lái | D5: 5 | E5: 0 | H5: 8
B6: Bài 3:Tập lái trong bãi phẳng . | C6: Sân tập lái | D6: 40 | E6: 200 | H6: 100
B7: - Tập lái đúng phần đường quy định.
B8: - Căn xe trên đường
B9: - Thay đổi số trên đường thẳng
B11: Bài 4: Tập lái trong hình số 3 và số 8 ghép, | C11: Sân tập lái | D11: 40 | E11: 200 | H11: 100
B12: tiến, lùi hình chữ chi
B13: - Tập lái xe trong hinh số 8 và số 3
B14: - Tiến và lùi trong hình chữ chi
B15: - Tập lái trong hình số 3,8 ghép và hình chữ chi
B17: Bài 5: Tập lái trên đường bằng | C17: Sân tập lái | D17: 40 | E17: 200 | H17: 100
B18: - Tập lái theo đúng phần đường quy định
B19: - Xử lý tình huống giao thông đơn giản
B20: - Dừng và đỗ xe đúng nơi quy định.
B22: Bài 6.: Bài tập lái xe tổng hợp | C22: Sân tập lái | D22: 75 | E22: 850 | H22: 204
B23: - Lái xe trong hình các bài thi sát hạch GV hướng dẫn
B24: - Học viên độc lập lái xe trên sa hình

Sheet IN DAT
B1: Tên HV:.................................................................... | C1: Ngày sinh…......................... | F1: Xe…........................
A2: Ngày tháng | B2: Nội dung bài giảng | C2: Địa điểm | D2: Số Giờ Thực Hành | E2: Số Km thực hành | F2: Số nhiên liệu sử dụng | G2: Chữ ký
B3: (Thực hành hạng B) | G3: Giáo Viên | H3: Trưởng Ban nghề
B4: Khóa : …..................................
B5: Bài 7: Tập lái trên đường cao tốc và cao tốc phân kỳ đầu tư | C5: Ngoài đường
B6: - Di chuyển xe theo tốc độ quy định
B7: - Tốc độ phù hợp, chuyển số phù hợp
B8: - Quan sát và xử lý khoảng cách an toàn
B9: - Phải tập trung, quan sát đúng huớng khi lái
B10: - Đảm bảo an toàn khi vào và ra cao tốc
B11: Bài 8: Tập lái trên đường dốc, đường vòng quanh co | C11: Ngoài đường
B12: - Tập lái xe căn lề trên đường, tập tắp lề
B13: - Phương pháp lái xe lên - xuống dốc
B14: - Di chuyển xe theo tốc độ quy định
B15: - Phán đoán, xử trí và thực hiện các biện pháp an toàn
B16: Bài 9: Tập lái trên đường phức tạp | C16: Ngoài đường
B17: - Tập lái qua khu vực đông xe qua lại
B18: - Di chuyển xe theo tốc độ quy định
B19: - Phải tập trung, quan sát đúng huớng khi lái
B20: - Qua ngã ba, ngã tư giao nhau,khu vực đường hẹp
B21: Bài 10: Tập lái ban đêm | C21: Ngoài đường
B22: - Quan sát và xử lý khoảng cách an toàn
B23: - Di chuyển xe theo tốc độ quy định
B24: - Phải tập trung, quan sát đúng huớng khi lái
B25: - Phải sử dụng đèn pha, cốt hợp lý
B26: - Đảm bảo an toàn khi rẽ trái hoặc phải
B27: - Ước lượng khoảng cách khi xe đi ngược chiều
B28: - Đi đúng phần đường
B29: - Phải lau chùi kính xe và chiếu hậu khi kiếng bị mờ
B30: - Tập đỗ xe và khởi hành
B31: Bài 11: Tập lái xe có tải | C31: Ngoài đường
B32: - Tốc độ phù hợp, chuyển số phù hợp
B33: - Phương pháp dừng và xuất phát khi có tải trọng
B34: - Quan sát và xử lý khoảng cách an toàn
B35: - Di chuyển xe theo tốc độ quy định
B36: - Đảm bảo an toàn khi rẽ trái hoặc phải
B37: Bài 12: Tập lái trên đường với xe ô tô số tự động | C37: Ngoài đường STĐ
B38: - Di chuyển xe theo tốc độ quy định
B39: - Quan sát và xử lý khoảng cách an toàn
B40: Thi tốt nghiệp
...
