Workbook

Sheet danh sách 1
A1: STT | B1: Họ và tên | C1: Ngày sinh | D1: Số CMND/ HC | E1: Địa chỉ thường trú | F1: GV
A2: 1 | B2: ĐỖ VĂN ĐỆ | C2: 01/01/1991 | D2: 094091007136 | E2: Ấp An Trung A X. An Thạnh 1, H. Cù Lao Dung, T. Sóc Trăng | F2: C LAN (LINH)
A3: 2 | B3: NGUYỄN THÀNH KHANG | C3: 10/11/2002 | D3: 082202008656 | E3: 148 Tổ 8 Khu 4 TT. Cái Bè, H. Cái Bè, T. Tiền Giang | F3: C LAN (LINH)
A4: 3 | B4: NGUYỄN MINH SƠN | C4: 24/10/1985 | D4: 080085017255 | E4: Số 288 Ấp 02 X. Long Khê, H. Cần Đước, T. Long An | F4: C LAN (LINH)
A5: 4 | B5: NGUYỄN PHÚ THỌ | C5: 15/02/2000 | D5: 096200000972 | E5: Tân Thành Lập X. Tân Đức, H. Đầm Dơi, T. Cà Mau | F5: C LAN (LINH)
A6: 5 | B6: TRẦN CÔNG MINH | C6: 29/03/1983 | D6: 089083023237 | E6: Long Châu P. Long Châu, TX. Tân Châu, T. An Giang | F6: C LAN( A THẮNG)
A7: 6 | B7: VÕ VĂN MINH | C7: 29/12/1976 | D7: 093076008923 | E7: Ấp 2 TT. Vĩnh Viễn, H. Long Mỹ, T. Hậu Giang | F7: DỰ
A8: 7 | B8: HUỲNH THANH SƠN | C8: 17/10/2003 | D8: 074203006096 | E8: Ấp Bến Tranh X. Thanh An, H. Dầu Tiếng, T. Bình Dương | F8: DỰ
A9: 8 | B9: LÊ THANH VÂN | C9: 19/02/1984 | D9: 074184002338 | E9: Ấp Thanh Tân X. Thanh An, H. Dầu Tiếng, T. Bình Dương | F9: DỰ
A10: 9 | B10: LÝ PHƯỚC SANG | C10: 24/12/1998 | D10: 072098009523 | E10: Ấp An Thuận X. Phú An, TX. Bến Cát, T. Bình Dương | F10: HÀ A1
A11: 10 | B11: NGÔ BÁ QUỐC | C11: 13/05/1997 | D11: 079097008313 | E11: 192/51 Phú Thọ Hòa P. Phú Thọ Hòa, Q. Tân Phú, TP. Hồ Chí Minh | F11: HOA VP
A12: 11 | B12: VÕ MINH HIẾU | C12: 26/01/1994 | D12: 080094007679 | E12: Ấp Hòa Bình 2 TT. Hiệp Hòa, H. Đức Hòa, T. Long An | F12: HUY TN
A13: 12 | B13: PHẠM VĂN MẠNH | C13: 20/02/1982 | D13: 038082019622 | E13: Thôn Hoa Trường X. Hoa Lộc, H. Hậu Lộc, T. Thanh Hóa | F13: HUY TN
... A33: 32 | B33: HỒ CÔNG THIỆN | C33: 25/03/2003 | D33: 082203017712 | E33: Ấp Tân Phú X. Tân Thành, H. Gò Công Đông, T. Tiền Giang | F33: THOA

Sheet DANH SÁCH
A1: HẠNG | C1: C1 | D1: KHÓA | G1: TÊN KHÓA | I1: K
A2: Nhóm | B2: STT | C2: Họ và tên | D2: Ngày sinh | E2: Số CMND | F2: Nơi cư trú | G2: GV | H2: XE SỐ SÀN | I2: GV | J2: STT | K2: GVKH | L2: Xe KH | M2: Hạn giấy phép xe tập lái
A3: 1 | B3: 1 | J3: 1
B4: 2 | J4: 2
B5: 3 | J5: 3
B6: 4 | J6: 4
B7: 5 | J7: 5
B8: 6 | J8: 6
A9: 2 | B9: 1 | J9: 7 | K9: LÊ ANH THIỆN | L9: 61K-073.35 | N9: TĐ
B10: 2 | J10: 8 | K10: VŨ TIẾN YÊN | L10: 51K381.17 | N10: TĐ
B11: 3 | J11: 9 | K11: CAO VĂN NAM | L11: 51H-463.82 | N11: TĐ
B12: 4 | J12: 10 | K12: NGUYỄN ĐÌNH HOÀI | L12: 51K349.49 | N12: TĐ
B13: 5 | J13: 11 | K13: TRẦN HỮU PHƯỚC | L13: 51L-19770 | N13: TĐ
B14: 6
A15: 3 | B15: 1
B16: 2
B17: 3
B18: 4
B19: 5
B20: 6
A21: 4 | B21: 1
B22: 2
B23: 3
B24: 4
B25: 5
B26: 6
A27: 5 | B27: 1
B28: 2
B29: 3
B30: 4
B31: 5
B32: 6
A33: 6 | B33: 1
B34: 2
B35: 3
B36: 4
B37: 5
B38: 6
A39: 7 | B39: 1
B40: 2
...

Sheet BÌA
C2: TRUNG TÂM GIÁO DỤC NGHỀ NGHIỆP TIẾN THÀNH
E5: SỔ THEO DÕI THỰC HÀNH LÁI XE
C10: Họ và tên giáo viên: | G10: ….......................................................
C11: Họ và tên giáo viên số tự động: | G11: ….......................................................
C13: Biển số xe tập lái số sàn: | G13: ….......................................................
C14: Biển số xe tập lái số tự động: | G14: ….......................................................
C16: Mã khóa: | E16: ................................... | H16: Tên khóa: | J16: …....... | K16: Hạng: | L16: C1
C18: Năm 202….

Sheet SỔ THEO DÕI
B1: Hạng xe: | C1: ….............. | D1: Từ ngày: | E1: ….................. | F1: đến ngày: | G1: …............
B2: Mã Khóa: | C2: ….............................................. | E2: Xe: | F2: …...........................
A4: DANH SÁCH HỌC VIÊN
A6: STT | B6: Họ và tên | C6: Ngày sinh | D6: Nơi cư trú | E6: Số km thực hành | F6: Điểm thi kiểm tra cuối khóa | G6: Học viên ký tên
A7: 1 | B7: ='DANH SÁCH'!C3 -> 0 | C7: ='DANH SÁCH'!D3 -> 0 | D7: ='DANH SÁCH'!F3 -> 0
A8: 2 | B8: ='DANH SÁCH'!C4 -> 0 | C8: ='DANH SÁCH'!D4 -> 0 | D8: ='DANH SÁCH'!F4 -> 0
A9: 3 | B9: ='DANH SÁCH'!C5 -> 0 | C9: ='DANH SÁCH'!D5 -> 0 | D9: ='DANH SÁCH'!F5 -> 0
A10: 4 | B10: ='DANH SÁCH'!C6 -> 0 | C10: ='DANH SÁCH'!D6 -> 0 | D10: ='DANH SÁCH'!F6 -> 0
A11: 5 | B11: ='DANH SÁCH'!C7 -> 0 | C11: ='DANH SÁCH'!D7 -> 0 | D11: ='DANH SÁCH'!F7 -> 0
A12: 6 | B12: ='DANH SÁCH'!C8 -> 0 | C12: ='DANH SÁCH'!D8 -> 0 | D12: ='DANH SÁCH'!F8 -> 0
B14: Hạng xe: | C14: ….............. | D14: Từ ngày: | E14: ….................. | F14: đến ngày: | G14: …............
B15: Mã Khóa: | C15: ….............................................. | E15: Xe: | F15: …...........................
A17: DANH SÁCH HỌC VIÊN
A19: STT | B19: Họ và tên | C19: Ngày sinh | D19: Nơi cư trú | E19: Số km thực hành | F19: Điểm thi kiểm tra cuối khóa | G19: Học viên ký tên
A20: 1 | B20: ='DANH SÁCH'!C9 -> 0 | C20: ='DANH SÁCH'!D9 -> 0 | D20: ='DANH SÁCH'!F9 -> 0
A21: 2 | B21: ='DANH SÁCH'!C10 -> 0 | C21: ='DANH SÁCH'!D10 -> 0 | D21: ='DANH SÁCH'!F10 -> 0
A22: 3 | B22: ='DANH SÁCH'!C11 -> 0 | C22: ='DANH SÁCH'!D11 -> 0 | D22: ='DANH SÁCH'!F11 -> 0
A23: 4 | B23: ='DANH SÁCH'!C12 -> 0 | C23: ='DANH SÁCH'!D12 -> 0 | D23: ='DANH SÁCH'!F12 -> 0
A24: 5 | B24: ='DANH SÁCH'!C13 -> 0 | C24: ='DANH SÁCH'!D13 -> 0 | D24: ='DANH SÁCH'!F13 -> 0
A25: 6 | B25: ='DANH SÁCH'!C14 -> 0 | C25: ='DANH SÁCH'!D14 -> 0 | D25: ='DANH SÁCH'!F14 -> 0
B26: Hạng xe: | C26: ….............. | D26: Từ ngày: | E26: ….................. | F26: đến ngày: | G26: …............
B27: Mã Khóa: | C27: ….............................................. | E27: Xe: | F27: …...........................
A29: DANH SÁCH HỌC VIÊN
A31: STT | B31: Họ và tên | C31: Ngày sinh | D31: Nơi cư trú | E31: Số km thực hành | F31: Điểm thi kiểm tra cuối khóa | G31: Học viên ký tên
A32: 1 | B32: ='DANH SÁCH'!C15 -> 0 | C32: ='DANH SÁCH'!D15 -> 0 | D32: ='DANH SÁCH'!F15 -> 0
A33: 2 | B33: ='DANH SÁCH'!C16 -> 0 | C33: ='DANH SÁCH'!D16 -> 0 | D33: ='DANH SÁCH'!F16 -> 0
A34: 3 | B34: ='DANH SÁCH'!C17 -> 0 | C34: ='DANH SÁCH'!D17 -> 0 | D34: ='DANH SÁCH'!F17 -> 0
A35: 4 | B35: ='DANH SÁCH'!C18 -> 0 | C35: ='DANH SÁCH'!D18 -> 0 | D35: ='DANH SÁCH'!F18 -> 0
A36: 5 | B36: ='DANH SÁCH'!C19 -> 0 | C36: ='DANH SÁCH'!D19 -> 0 | D36: ='DANH SÁCH'!F19 -> 0
A37: 6 | B37: ='DANH SÁCH'!C20 -> 0 | C37: ='DANH SÁCH'!D20 -> 0 | D37: ='DANH SÁCH'!F20 -> 0
B38: Hạng xe: | C38: ….............. | D38: Từ ngày: | E38: ….................. | F38: đến ngày: | G38: …............
B39: Mã Khóa: | C39: ….............................................. | E39: Xe: | F39: …...........................
A41: DANH SÁCH HỌC VIÊN
A43: STT | B43: Họ và tên | C43: Ngày sinh | D43: Nơi cư trú | E43: Số km thực hành | F43: Điểm thi kiểm tra cuối khóa | G43: Học viên ký tên
A44: 1 | B44: ='DANH SÁCH'!C21 -> 0 | C44: ='DANH SÁCH'!D21 -> 0 | D44: ='DANH SÁCH'!F21 -> 0
A45: 2 | B45: ='DANH SÁCH'!C22 -> 0 | C45: ='DANH SÁCH'!D22 -> 0 | D45: ='DANH SÁCH'!F22 -> 0
A46: 3 | B46: ='DANH SÁCH'!C23 -> 0 | C46: ='DANH SÁCH'!D23 -> 0 | D46: ='DANH SÁCH'!F23 -> 0
A47: 4 | B47: ='DANH SÁCH'!C24 -> 0 | C47: ='DANH SÁCH'!D24 -> 0 | D47: ='DANH SÁCH'!F24 -> 0
A48: 5 | B48: ='DANH SÁCH'!C25 -> 0 | C48: ='DANH SÁCH'!D25 -> 0 | D48: ='DANH SÁCH'!F25 -> 0
A49: 6 | B49: ='DANH SÁCH'!C26 -> 0 | C49: ='DANH SÁCH'!D26 -> 0 | D49: ='DANH SÁCH'!F26 -> 0
...

Sheet MẪU HÌNH
A1: Ngày tháng | B1: Nội dung bài giảng | C1: Địa điểm | D1: Số Giờ Thực Hành | E1: Số Km thực hành | F1: Họ tên Hs vắng mặt | H1: Số nhiên liệu sử dụng | I1: Chữ ký
B2: (Thực hành hạng C1) | F2: có lý do | G2: không có lý do | I2: Giáo Viên | J2: Trưởng Ban nghề
B3: Khóa : …..................................
A4: 45658 | B4: Bài 1:Tập lái tại chỗ không nổ máy. | C4: Sân tập lái | D4: 7 | E4: 0 | H4: 0
B5: Bài 2: Tập lái tại chỗ có nổ máy. | C5: Sân tập lái | D5: 7 | H5: =D5*1.4 -> 9.8
A6: =A4 -> 45658 | D6: 3 | H6: =D6*1.4 -> 4.2
A7: =A6+1 -> 45659 | D7: 4 | H7: =D7*1.4 -> 5.6
B8: Bài 3:Tập lái trong bãi phẳng . | C8: Sân tập lái | D8: 56 | E8: =D8*5 -> 280 | H8: =D8*1.6 -> 89.6
A9: =A6+1 -> 45659 | B9: - Tập lái đúng phần đường quy định. | D9: 6 | E9: =D9*5 -> 30 | H9: =D9*1.6 -> 9.6
A10: =A9+1 -> 45660 | B10: - Căn xe trên đường | D10: 10 | E10: =D10*5 -> 50 | H10: =D10*1.6 -> 16 | M10: GIỜ/7HV/1XE | N10: KM/7HV/1XE | O10: TỔNG
A11: =A10+1 -> 45661 | B11: - Thay đổi số trên đường thẳng | D11: 10 | E11: =D11*5 -> 50 | H11: =D11*1.6 -> 16 | L11: sa hình | M11: =43*7 -> 301 | N11: =275*7 -> 1925
A12: =A11+1 -> 45662 | D12: 10 | E12: =D12*5 -> 50 | H12: =D12*1.6 -> 16 | L12: Hạng C1 | M12: 1hv/xe (giờ) | N12: 7hv/xe (giờ)
A13: =A12+1 -> 45663 | D13: 10 | E13: =D13*5 -> 50 | H13: =D13*1.6 -> 16 | L13: Bài 1:Tập lái tại chỗ không nổ máy. | M13: 1 | N13: 7 | O13: SA HÌNH 43 giờ/1hv 301 giờ/7hv
A14: =A13+1 -> 45664 | D14: 10 | E14: =D14*5 -> 50 | H14: =D14*1.6 -> 16 | L14: Bài 2: Tập lái tại chỗ có nổ máy. | M14: 1 | N14: 7
B15: Bài 4: Tập lái trong hình số 3 và số 8 ghép, tiến, lùi hình chữ chi | C15: Sân tập lái | D15: 56 | E15: =D15*5 -> 280 | H15: =D15*1.6 -> 89.6 | L15: Bài 3:Tập lái trong bãi phẳng . | M15: 8 | N15: 56
L16: Bài 4: Tập lái trong hình số 3 và số 8 ghép, tiến, lùi hình chữ chi | M16: 8 | N16: 56
A17: =A14+1 -> 45665 | B17: - Tập lái xe trong hinh số 8 và số 3 | D17: 10 | E17: =D17*5 -> 50 | H17: =D17*1.6 -> 16 | L17: Bài 5: Tập lái trên đường bằng | M17: 8 | N17: 56
A18: =A17+1 -> 45666 | B18: - Tiến và lùi trong hình chữ chi | D18: 10 | E18: =D18*5 -> 50 | H18: =D18*1.6 -> 16 | L18: Bài 6: Bài tập lái xe tổng hợp | M18: 17 | N18: 119
A19: =A18+1 -> 45667 | B19: - Tập lái trong hình số 3,8 ghép và hình chữ chi | D19: 10 | E19: =D19*5 -> 50 | H19: =D19*1.6 -> 16 | L19: Bài 7: Tập lái trên đường cao tốc và cao tốc phân kỳ đầu tư | M19: 10 | N19: 70 | O19: ĐƯỜNG 48 giờ/1hv 336 giờ/7hv
A20: =A19+1 -> 45668 | B20: - Tập lái xe trong sa hình, ghép dọc | D20: 10 | E20: =D20*5 -> 50 | H20: =D20*1.6 -> 16 | L20: Bài 8: Tập lái xe trên đường dốc, đường vòng quanh co | M20: 10 | N20: 70
A21: =A20+1 -> 45669 | D21: 10 | E21: =D21*5 -> 50 | H21: =D21*1.6 -> 16 | L21: Bài 9: Tập lái trên đường phức tạp | M21: 12 | N21: 84
A22: =A21+1 -> 45670 | D22: 6 | E22: =D22*5 -> 30 | H22: =D22*1.6 -> 9.6 | L22: Bài 10: Tập lái ban đêm | M22: 2 | N22: 14
B23: Bài 5: Tập lái trên đường bằng | C23: Sân tập lái | D23: 56 | E23: =D23*5 -> 280 | H23: =D23*1.6 -> 89.6 | L23: Bài 11: Tập lái xe có tải | M23: 12 | N23: 84
A24: =A22 -> 45670 | B24: - Tập lái theo đúng phần đường quy định | D24: 4 | E24: =D24*5 -> 20 | H24: =D24*1.6 -> 6.4 | L24: Bài 12: Tập lái trên đường với xe ô tô số tự động | M24: 2 | N24: 14
A25: =A24+1 -> 45671 | B25: - Xử lý tình huống giao thông đơn giản | D25: 10 | E25: =D25*5 -> 50 | H25: =D25*1.6 -> 16
A26: =A25+1 -> 45672 | B26: - Dừng và đỗ xe đúng nơi quy định. | D26: 10 | E26: =D26*5 -> 50 | H26: =D26*1.6 -> 16
A27: =A26+1 -> 45673 | D27: 10 | E27: =D27*5 -> 50 | H27: =D27*1.6 -> 16
A28: =A27+1 -> 45674 | D28: 10 | E28: =D28*5 -> 50 | H28: =D28*1.6 -> 16
A29: =A28+1 -> 45675 | D29: 10 | E29: =D29*5 -> 50 | H29: =D29*1.6 -> 16
A30: =A29+1 -> 45676 | D30: 2 | E30: =D30*5 -> 10 | H30: =D30*1.6 -> 3.2
B31: Bài 6: Bài tập lái xe tổng hợp | C31: Sân tập lái | D31: 119 | E31: 930 | H31: =D31*1.8 -> 214.2
A32: =A30+1 -> 45677 | B32: - Lái xe trong hình các bài thi sát hạch GV hướng dẫn | D32: 9 | E32: =D32*(E31/D31) -> 70.336134 | H32: =D32*1.8 -> 16.2
A33: =A32+1 -> 45678 | B33: - Học viên độc lập lái xe trên sa hình | D33: 10 | E33: =D33*(E32/D32) -> 78.151261 | H33: =D33*1.8 -> 18
A34: =A33+1 -> 45679 | D34: 10 | E34: =D34*(E33/D33) -> 78.151261 | H34: =D34*1.8 -> 18
A35: =A34+1 -> 45680 | D35: 10 | E35: =D35*(E34/D34) -> 78.151261 | H35: =D35*1.8 -> 18
A36: =A35+1 -> 45681 | D36: 10 | E36: =D36*(E35/D35) -> 78.151261 | H36: =D36*1.8 -> 18
A37: =A36+1 -> 45682 | D37: 10 | E37: =D37*(E35/D35) -> 78.151261 | H37: =D37*1.8 -> 18
A38: =A37+1 -> 45683 | D38: 10 | E38: =D38*(E37/D37) -> 78.151261 | H38: =D38*1.8 -> 18
A39: =A38+1 -> 45684 | D39: 10 | E39: =D39*(E38/D38) -> 78.151261 | H39: =D39*1.8 -> 18
A40: =A39+1 -> 45685 | D40: 10 | E40: =D40*(E39/D39) -> 78.151261 | H40: =D40*1.8 -> 18
...

Sheet Sheet1
A1: 45658
A2: 45659
A3: 45660
A4: 45661
A5: 45662
A6: 45663
A7: 45664
A8: 45665
A9: 45666
A10: 45667
A11: 45668
A12: 45669
... A31: 45688

Sheet IN SA HÌNH
A1: Ngày tháng | B1: Nội dung bài giảng | C1: Địa điểm | D1: Số Giờ Thực Hành | E1: Số Km thực hành | F1: Họ tên Hs vắng mặt | H1: Số nhiên liệu sử dụng | I1: Chữ ký
B2: (Thực hành hạng C1) | F2: có lý do | G2: không có lý do | I2: Giáo Viên | J2: Trưởng Ban nghề
B3: Khóa : …..................................
B4: Bài 1:Tập lái tại chỗ không nổ máy. | C4: Sân tập lái | D4: 6 | E4: 0 | H4: 0
B5: Bài 2: Tập lái tại chỗ có nổ máy. | C5: Sân tập lái | D5: 6 | H5: =D5*1.4 -> 8.4
B8: Bài 3:Tập lái trong bãi phẳng . | C8: Sân tập lái | D8: 48 | E8: =D8*5 -> 240 | H8: =D8*1.6 -> 76.8
B9: - Tập lái đúng phần đường quy định.
B10: - Căn xe trên đường
B12: - Thay đổi số trên đường thẳng
B14: Bài 4: Tập lái trong hình số 3 và số 8 ghép, tiến, lùi hình chữ chi | C14: Sân tập lái | D14: 48 | E14: =D14*5 -> 240 | H14: =D14*1.6 -> 76.8
B16: - Tập lái xe trong hinh số 8 và số 3
B17: - Tiến và lùi trong hình chữ chi
B18: - Tập lái trong hình số 3,8 ghép và hình chữ chi
B19: - Tập lái xe trong sa hình, ghép dọc
B21: Bài 5: Tập lái trên đường bằng | C21: Sân tập lái | D21: 48 | E21: =D21*5 -> 240 | H21: =D21*1.6 -> 76.8
B22: - Tập lái theo đúng phần đường quy định
B23: - Xử lý tình huống giao thông đơn giản
B24: - Dừng và đỗ xe đúng nơi quy định.
B27: Bài 6: Bài tập lái xe tổng hợp | C27: Sân tập lái | D27: 102 | E27: 930 | H27: =D27*1.8 -> 183.6
B28: - Lái xe trong hình các bài thi sát hạch GV hướng dẫn
B29: - Học viên độc lập lái xe trên sa hình

Sheet DAT
B1: Tên HV:.................................................................... | C1: Ngày sinh…......................... | F1: Xe…........................
A2: Ngày tháng | B2: Nội dung bài giảng | C2: Địa điểm | D2: Số Giờ Thực Hành | E2: Số Km thực hành | F2: Số nhiên liệu sử dụng | G2: Chữ ký
B3: (Thực hành hạng C1) | G3: Giáo Viên | H3: Trưởng Ban nghề
B4: Khóa : …..................................
B5: Bài 7: Tập lái trên đường cao tốc và cao tốc phân kỳ đầu tư | C5: Ngoài đường
B6: - Di chuyển xe theo tốc độ quy định
B7: - Tốc độ phù hợp, chuyển số phù hợp
B8: - Quan sát và xử lý khoảng cách an toàn
B9: - Phải tập trung, quan sát đúng huớng khi lái
B10: - Đảm bảo an toàn khi vào và ra cao tốc
B11: Bài 8: Tập lái xe trên đường dốc, đường vòng quanh co | C11: Ngoài đường
B12: - Tập lái xe căn lề trên đường, tập tắp lề
B13: - Phương pháp lái xe lên - xuống dốc
B14: - Di chuyển xe theo tốc độ quy định
B15: - Phán đoán, xử trí và thực hiện các biện pháp an toàn
B16: Bài 9: Tập lái trên đường phức tạp | C16: Ngoài đường
B17: - Tập lái qua khu vực đông xe qua lại
B18: - Di chuyển xe theo tốc độ quy định
B19: - Phải tập trung, quan sát đúng huớng khi lái
B20: - Qua ngã ba, ngã tư giao nhau,khu vực đường hẹp
B21: Bài 10: Tập lái ban đêm | C21: Ngoài đường
B22: - Quan sát và xử lý khoảng cách an toàn
B23: - Di chuyển xe theo tốc độ quy định
B24: - Phải tập trung, quan sát đúng huớng khi lái
B25: - Phải sử dụng đèn pha, cốt hợp lý
B26: - Đảm bảo an toàn khi rẽ trái hoặc phải
B27: - Ước lượng khoảng cách khi xe đi ngược chiều
B28: - Đi đúng phần đường
B29: - Phải lau chùi kính xe và chiếu hậu khi kiếng bị mờ
B30: - Tập đỗ xe và khởi hành
B31: Bài 11: Tập lái xe có tải | C31: Ngoài đường
B32: - Tốc độ phù hợp, chuyển số phù hợp
B33: - Phương pháp dừng và xuất phát khi có tải trọng
B34: - Quan sát và xử lý khoảng cách an toàn
B35: - Di chuyển xe theo tốc độ quy định
B36: - Đảm bảo an toàn khi rẽ trái hoặc phải
B37: Bài 12: Tập lái trên đường với xe ô tô số tự động | C37: Ngoài đường STĐ
B38: - Di chuyển xe theo tốc độ quy định
B39: - Quan sát và xử lý khoảng cách an toàn
B40: Thi tốt nghiệp
...
